Workbook

Sheet param_list_and_type
A1: area | B1: component | C1: id | D1: label | E1: type | F1: adult_inf | G1: infant_inf | H1: first_90 | I1: sec_90 | J1: third_90 | K1: deaths
A2: TREATMENT | B2: art_cont | C2: art_provision | D2: ART provision for all | E2: coverage | F2: X | I2: X | J2: X | K2: X | L2: include cotrimoxazole here
A3: TREATMENT | B3: art_cont | C3: mmd | D3: MMD (multi-month dispensing) | E3: coverage | F3: X | I3: X | J3: X
A4: TREATMENT | B4: art_cont | C4: dsd | D4: DSD (differentiated service delivery) | E4: coverage | F4: X | I4: X | J4: X
A5: TREATMENT | B5: oi_prophylaxis | C5: cotrim | D5: Cotrimoxazole prophylaxis | E5: coverage | K5: X
A6: TREATMENT | B6: art_init | C6: art_init | D6: ART initiation (and re-initiation) | E6: absolute | F6: X | G6: X | I6: X | J6: X | K6: X | L6: I'm wondering actually if the elements that are chained may affect fewer outcomes?
A7: TREATMENT | B7: vl_monitoring | C7: vl_targeted | D7: VL monitoring: suspected failure | E7: absolute | J7: X | L7: For example we know ART impacts mortality, but first it impacts viral suppression
A8: TREATMENT | B8: vl_monitoring | C8: vl_routine | D8: Routine VL monitoring | E8: absolute | J8: X | L8: and that’s theparameter that impacts mortality? Rather than both simultaneously
A9: TREATMENT | B9: oi_managment | C9: oi_tb_test | D9: OI: TB testing for symptomatic | E9: absolute | K9: X
A10: TREATMENT | B10: oi_managment | C10: oi_tb_tpt | D10: OI: TB preventive therapy (TPT) | E10: coverage | K10: X
A11: TREATMENT | B11: oi_managment | C11: oi_tb_tx | D11: OI: TB treatment | E11: coverage | K11: X
A12: TREATMENT | B12: oi_managment | C12: oi_crypto_tx | D12: OI: Cryptococcal treatment | E12: coverage | K12: X
A13: TREATMENT | B13: ahd | C13: ahd_lam | D13: AHD: LAM for Stage 3/4 / seriously ill | E13: absolute | K13: X
A14: TREATMENT | B14: ahd | C14: ahd_crag | D14: AHD: CRAG for Stage 3/4 / IPD | E14: absolute | K14: X
A15: TREATMENT | B15: ahd | C15: ahd_cd4 | D15: AHD: CD4 testing | E15: absolute | K15: X
A16: TREATMENT | B16: ahd | C16: ahd_flucon | D16: AHD: Pre-emptive fluconazole | E16: absolute | K16: X
A17: TREATMENT | B17: tracking | C17: tracking_total | D17: Tracking & tracing (total) | E17: absolute (number of calls)? Not sure | I17: X | J17: X | K17: X
A18: TREATMENT | B18: psychoscocial | C18: fac_education | D18: Facility Patient Education | E18: coverage | I18: X | J18: X | K18: X
A19: TREATMENT | B19: psychoscocial | C19: adh_couns | D19: Adherence Counselling | E19: coverage | I19: X | J19: X | K19: X
A20: TREATMENT | B20: psychoscocial | C20: psychosocial | D20: Psychosocial support / counselling | E20: coverage | I20: X | J20: X | K20: X
A21: TESTING | B21: test_facility | C21: test_facility | D21: Testing: facility-based | E21: absolute | H21: X | I21: X
A22: TESTING | B22: test_community | C22: test_community | D22: Testing: community-based | E22: absolute | H22: X | I22: X
A23: TESTING | B23: test_kpsti | C23: test_kpsti | D23: Testing: key populations & STI services | E23: absolute | H23: X | I23: X
A24: TESTING | B24: hivst | C24: hivst_fac | D24: HIVST (Facility-based) | E24: absolute | H24: X | I24: X
A25: TESTING | B25: hivst | C25: hivst_com | D25: HIVST (community-based) | E25: absolute | H25: X | I25: X
A26: PREVENTION | B26: infant_prophylaxis | C26: infant_proph | D26: Infant prophylaxis | E26: absolute | G26: X
A27: PREVENTION | B27: pep | C27: pep | D27: PEP | E27: absolute | F27: X | L27: For all prevention we may need elemenst of adherence or uptake alonside effect
A28: PREVENTION | B28: condoms | C28: condoms | D28: Condom availability | E28: absolute | F28: X | L28: e.g if 70% of those eligble for prep inititate, 80% adhere and theres a 90% effectiveness
A29: PREVENTION | B29: prep | C29: prep_oral | D29: PrEP (oral) | E29: coverage | F29: X | L29: pop_prep
A30: PREVENTION | B30: prep | C30: prep_cabla | D30: PrEP (CAB-LA) | E30: coverage | F30: X
A31: PREVENTION | B31: prep | C31: prep_len | D31: PrEP (Lenacapavir) | E31: coverage | F31: X
A32: PREVENTION | B32: vmmc | C32: vmmc | D32: VMMC | E32: absolute? | F32: X
A33: ANC | B33: anc_hiv_test | D33: ANC: HIV testing | E33: coverage | G33: X | H33: X
A34: ANC | B34: eID | D34: EID (early infant diagnosis) | E34: coverage | H34: X | J34: X
A35: ANC | B35: anc_vl_testing | D35: ANC: Viral Load Testing | E35: coverage | G35: X | I35: X

Sheet tier_plus_updated
E1: Type: if 'absolute' the user can enter the precise number of services provided (e.g. 1.1million tests, 50,000 VMMCs, etc) | F1: Outcome affected
A2: area | B2: component | C2: label | D2: Interval | E2: type | F2: adult infections | G2: infant infections | H2: first 95 | I2: second 95 | J2: third 95 | K2: mortality
A3: TREATMENT | B3: art_cont | C3: ART provision for all | E3: coverage | F3: X | I3: X | J3: X | K3: X
A4: TREATMENT | B4: art_cont | C4: MMD (multi-month dispensing) | D4: 3, 6, 12 months | E4: coverage | F4: X | I4: X | J4: X
A5: TREATMENT | B5: oi_prophylaxis | C5: Cotrimoxazole prophylaxis | E5: coverage | K5: X
A6: TREATMENT | B6: art_init | C6: ART initiation (and re-initiation) | E6: absolute | F6: X | G6: X | I6: X | J6: X | K6: X
A7: TREATMENT | B7: vl_monitoring | C7: VL monitoring: suspected failure | E7: absolute | J7: X
A8: TREATMENT | B8: vl_monitoring | C8: Routine VL monitoring | D8: every 12 or 24 months | E8: coverage | J8: X
A9: TREATMENT | B9: oi_managment | C9: Test for and treat Ois | E9: coverage | K9: X
A10: TREATMENT | B10: ahd | C10: AHD testing package (LAM, CrAG, CD4, fluconazole) | E10: absolute | K10: X
A11: TREATMENT | B11: tracking | C11: Tracking & tracing (total) | E11: coverage | I11: X | J11: X | K11: X
A12: TREATMENT | B12: psychoscocial | C12: Adherence Counselling/ psychosocial support | E12: coverage | I12: X | J12: X | K12: X
A13: TESTING | B13: test_facility | C13: Testing: facility-based | E13: absolute | H13: X | I13: X
A14: TESTING | B14: test_community | C14: Testing: community-based | E14: absolute | H14: X | I14: X
A15: TESTING | B15: test_kpsti | C15: Testing: for key populations & STI services | E15: absolute | H15: X | I15: X
A16: TESTING | B16: hivst | C16: HIVST (Facility-based) | E16: absolute | H16: X | I16: X
A17: TESTING | B17: hivst | C17: HIVST (community-based) | E17: absolute | H17: X | I17: X
A18: PREVENTION | B18: infant_prophylaxis | C18: Infant prophylaxis | E18: coverage | G18: X
A19: PREVENTION | B19: pep | C19: PEP | E19: absolute | F19: X
A20: PREVENTION | B20: condoms | C20: Condom availability | E20: absolute | F20: X
A21: PREVENTION | B21: prep | C21: PrEP (oral), person years | E21: absolute | F21: X
A22: PREVENTION | B22: prep | C22: PrEP (Lenacapavir), person years | E22: absolute | F22: X
A23: PREVENTION | B23: vmmc | C23: VMMC | E23: absolute | F23: X
A24: ANC | B24: anc_hiv_test | C24: ANC: HIV testing | E24: coverage | G24: X | H24: X
A25: ANC | B25: EID | C25: EID (early infant diagnosis) | E25: coverage | H25: X | K25: X
A26: ANC | B26: anc_vl_testing | C26: ANC: Viral Load Testing | E26: coverage | G26: X | J26: X
A29: https://bushare-my.sharepoint.com/:x:/g/personal/brooken_bu_edu/IQCrAqcnpglYQbFHxzN39mrIAddSipC0bePCNG6CgXoCMBk?e=5xvACO

Sheet tier_plus_30Jan
E1: Type: if 'absolute' the user can enter the precise number of services provided (e.g. 1.1million tests, 50,000 VMMCs, etc) | F1: Outcome affected
A2: area | B2: component | C2: label | D2: Interval | E2: type | F2: adult infections | G2: infant infections | H2: first 95 | I2: second 95 | J2: third 95 | K2: mortality
A3: TREATMENT | B3: art_cont | C3: ART provision for all | E3: coverage | F3: X | I3: X | J3: X | K3: X
A4: TREATMENT | B4: art_cont | C4: MMD (multi-month dispensing) | D4: 3, 6, 12 months | E4: coverage | F4: X | I4: X | J4: X
A5: TREATMENT | B5: oi_prophylaxis | C5: Cotrimoxazole prophylaxis (according to guidelines) | E5: coverage | K5: X
A6: TREATMENT | B6: art_init | C6: ART initiation (and re-initiation) | E6: absolute | F6: X | G6: X | I6: X | J6: X | K6: X
A7: TREATMENT | B7: vl_monitoring | C7: VL monitoring: suspected failure | E7: absolute | F7: X | J7: X | K7: X
A8: TREATMENT | B8: vl_monitoring | C8: Routine VL monitoring | D8: every 12 or 24 months | E8: coverage | F8: X | J8: X | K8: X
A9: TREATMENT | B9: tb_test_treat | C9: TB Screening and Treatment | E9: coverage | K9: X
A10: TREATMENT | B10: tpt | C10: TPT provision | E10: coverage | K10: X
A11: TREATMENT | B11: ahd | C11: AHD testing and prophylaxis package (LAM, CrAG, CD4, fluconazole) | E11: absolute | K11: X
A12: TREATMENT | B12: tracking | C12: Tracking & tracing (total) | E12: coverage | F12: X | I12: X | J12: X | K12: X
A13: TREATMENT | B13: cags | C13: Community ART Groups | E13: coverage | F13: X | I13: X | J13: X
A14: TREATMENT | B14: psychoscocial | C14: Adherence Counselling/ psychosocial support | E14: coverage | I14: X | J14: X | K14: X
A15: TESTING | B15: test_facility | C15: Testing: facility-based (general) | E15: absolute | H15: X | I15: X | J15: X
A16: TESTING | B16: test_facility | C16: Testing: facility-based (targeted) | E16: absolute | H16: X | I16: X | J16: X
A17: TESTING | B17: test_facility | C17: Testing: Network/Index | E17: absolute | H17: X | I17: X | J17: X
A18: TESTING | B18: test_community | C18: Testing: community-based | E18: absolute | H18: X | I18: X | J18: X
A19: TESTING | B19: test_kpsti | C19: Testing: for key populations & STI services | E19: absolute | H19: X | I19: X | J19: X
A20: TESTING | B20: hivst | C20: HIVST (Facility-based) | E20: absolute | H20: X | I20: X | J20: X
A21: TESTING | B21: hivst | C21: HIVST (community-based) | E21: absolute | H21: X | I21: X | J21: X
A22: PREVENTION | B22: infant_prophylaxis | C22: Infant prophylaxis | E22: coverage | G22: X
A23: PREVENTION | B23: pep | C23: PEP | E23: absolute | F23: X
A24: PREVENTION | B24: condoms | C24: Condom availability | E24: absolute | F24: X
A25: PREVENTION | B25: prep | C25: PrEP (oral), person years | E25: absolute | F25: X
A26: PREVENTION | B26: prep | C26: PrEP (Lenacapavir), person years | E26: absolute | F26: X
A27: PREVENTION | B27: vmmc | C27: VMMC | E27: absolute | F27: X
A28: ANC | B28: anc_hiv_test | C28: ANC: HIV testing | E28: coverage | G28: X | H28: X
A29: ANC | B29: EID | C29: EID (early infant diagnosis) | E29: coverage | H29: X | K29: X
A30: ANC | B30: anc_vl_testing | C30: ANC: Viral Load Testing | E30: coverage | G30: X | J30: X
A31: PNC | B31: pnc_hiv_test | C31: PNC: HIV testing | E31: coverage | G31: X | H31: X
A32: PNC | B32: pnc_vl_testing | C32: PNC: Viral Load Testing | E32: coverage | G32: X | J32: X
A33: PNC | B33: pnc_art_cont | C33: PNC: ART continuation | E33: coverage | F33: X | G33: X | I33: X | J33: X | K33: X

Sheet baseline_data
A1: Type | B1: Variables
A2: Epidemic params | B2: PLHIV
A3: Epidemic params | B3: # Diagnosed
A4: Epidemic params | B4: # On ART
A5: Epidemic params | B5: #Virally Suppressed
A6: Epidemic params | B6: HIV/TB coinfection rate
A7: Epidemic params | B7: HIV/cryptococcal co-infection rate
A8: Epidemic params | B8: Something like loss to follow-up?
A9: Epidemic params | B9: Proportion AHD
A10: Epidemic params | B10: Something about the number of individuals eligible for DSD?
A11: Epidemic params | B11: MMD availability (1 month/ 3 month/6 month)
A12: Epidemic params | B12: Percentage indiviudals requiring psychosocial support
... A17: Population denoms | B17: Adult population reached by services
A18: Population denoms | B18: Pregnant population | E18: is this HIV + pregnant population?
A19: Population denoms | B19: Infant population
A20: Population denoms | B20: Population receiving prep
A22: Some value around those at risk of failure and in need of adherence (althohgh this could be all those not virally suppressed)
A23: Shouold everyone get psychosocial counselling - not everyone may need so would only impact a proprtion of the pop but I am unsure what that denominator would be
A24: ^ maybe for this, we could do a coverage thing, where we say that some percent of people need psychosocial counselling, and then coverage goes from 0-100. (maybe we can find in literature)

Sheet params_effect
A1: area | B1: component | C1: id | D1: label | E1: outcome | F1: incremental_effect | G1: effect_value | H1: effect_calc | I1: notes | J1: source
A2: TREATMENT | B2: art_cont | C2: art_provision | D2: ART provision for all | E2: adult_inf | F2: {=IF( INDEX( param_list_and_type!$F:$K, MATCH(1, (param_list_and_type!$A:$A=A2)* (param_list_and_type!$B:$B=B2)* (param_list_and_type!$C:$C=C2), 0), MATCH(E2, param_list_and_type!$F$1:$K$1, 0) )="X", "Yes", "No" )} -> Yes | I2: 93% reduction in transmission among those adherent on ART | J2: (HPTN 052 study) | L2: Things not in og app mock-up
A3: TREATMENT | B3: art_cont | C3: art_provision | D3: ART provision for all | E3: infant_inf | F3: {=IF( INDEX( param_list_and_type!$F:$K, MATCH(1, (param_list_and_type!$A:$A=A3)* (param_list_and_type!$B:$B=B3)* (param_list_and_type!$C:$C=C3), 0), MATCH(E3, param_list_and_type!$F$1:$K$1, 0) )="X", "Yes", "No" )} -> No | G3: 0
A4: TREATMENT | B4: art_cont | C4: art_provision | D4: ART provision for all | E4: first_90 | F4: {=IF( INDEX( param_list_and_type!$F:$K, MATCH(1, (param_list_and_type!$A:$A=A4)* (param_list_and_type!$B:$B=B4)* (param_list_and_type!$C:$C=C4), 0), MATCH(E4, param_list_and_type!$F$1:$K$1, 0) )="X", "Yes", "No" )} -> No | G4: 0 | K4: 0 | L4: indicates there was no effect (based on original X's)
A5: TREATMENT | B5: art_cont | C5: art_provision | D5: ART provision for all | E5: sec_90 | F5: {=IF( INDEX( param_list_and_type!$F:$K, MATCH(1, (param_list_and_type!$A:$A=A5)* (param_list_and_type!$B:$B=B5)* (param_list_and_type!$C:$C=C5), 0), MATCH(E5, param_list_and_type!$F$1:$K$1, 0) )="X", "Yes", "No" )} -> Yes
A6: TREATMENT | B6: art_cont | C6: art_provision | D6: ART provision for all | E6: third_90 | F6: {=IF( INDEX( param_list_and_type!$F:$K, MATCH(1, (param_list_and_type!$A:$A=A6)* (param_list_and_type!$B:$B=B6)* (param_list_and_type!$C:$C=C6), 0), MATCH(E6, param_list_and_type!$F$1:$K$1, 0) )="X", "Yes", "No" )} -> Yes
A7: TREATMENT | B7: art_cont | C7: art_provision | D7: ART provision for all | E7: deaths | F7: {=IF( INDEX( param_list_and_type!$F:$K, MATCH(1, (param_list_and_type!$A:$A=A7)* (param_list_and_type!$B:$B=B7)* (param_list_and_type!$C:$C=C7), 0), MATCH(E7, param_list_and_type!$F$1:$K$1, 0) )="X", "Yes", "No" )} -> Yes
A8: TREATMENT | B8: art_cont | C8: mmd | D8: MMD (multi-month dispensing) | E8: adult_inf | F8: {=IF( INDEX( param_list_and_type!$F:$K, MATCH(1, (param_list_and_type!$A:$A=A8)* (param_list_and_type!$B:$B=B8)* (param_list_and_type!$C:$C=C8), 0), MATCH(E8, param_list_and_type!$F$1:$K$1, 0) )="X", "Yes", "No" )} -> Yes
A9: TREATMENT | B9: art_cont | C9: mmd | D9: MMD (multi-month dispensing) | E9: infant_inf | F9: {=IF( INDEX( param_list_and_type!$F:$K, MATCH(1, (param_list_and_type!$A:$A=A9)* (param_list_and_type!$B:$B=B9)* (param_list_and_type!$C:$C=C9), 0), MATCH(E9, param_list_and_type!$F$1:$K$1, 0) )="X", "Yes", "No" )} -> No | G9: 0
A10: TREATMENT | B10: art_cont | C10: mmd | D10: MMD (multi-month dispensing) | E10: first_90 | F10: {=IF( INDEX( param_list_and_type!$F:$K, MATCH(1, (param_list_and_type!$A:$A=A10)* (param_list_and_type!$B:$B=B10)* (param_list_and_type!$C:$C=C10), 0), MATCH(E10, param_list_and_type!$F$1:$K$1, 0) )="X", "Yes", "No" )} -> No | G10: 0
A11: TREATMENT | B11: art_cont | C11: mmd | D11: MMD (multi-month dispensing) | E11: sec_90 | F11: {=IF( INDEX( param_list_and_type!$F:$K, MATCH(1, (param_list_and_type!$A:$A=A11)* (param_list_and_type!$B:$B=B11)* (param_list_and_type!$C:$C=C11), 0), MATCH(E11, param_list_and_type!$F$1:$K$1, 0) )="X", "Yes", "No" )} -> Yes | I11: 4%-9% increase in retention over the SOC for 3-6 MMD | J11: Malawi& Zambia: https://www.sciencedirect.com/science/article/pii/S2214109X21000395
A12: TREATMENT | B12: art_cont | C12: mmd | D12: MMD (multi-month dispensing) | E12: third_90 | F12: {=IF( INDEX( param_list_and_type!$F:$K, MATCH(1, (param_list_and_type!$A:$A=A12)* (param_list_and_type!$B:$B=B12)* (param_list_and_type!$C:$C=C12), 0), MATCH(E12, param_list_and_type!$F$1:$K$1, 0) )="X", "Yes", "No" )} -> Yes
A13: TREATMENT | B13: art_cont | C13: mmd | D13: MMD (multi-month dispensing) | E13: deaths | F13: {=IF( INDEX( param_list_and_type!$F:$K, MATCH(1, (param_list_and_type!$A:$A=A13)* (param_list_and_type!$B:$B=B13)* (param_list_and_type!$C:$C=C13), 0), MATCH(E13, param_list_and_type!$F$1:$K$1, 0) )="X", "Yes", "No" )} -> No | G13: 0
A14: TREATMENT | B14: art_cont | C14: dsd | D14: DSD (differentiated service delivery) | E14: adult_inf | F14: {=IF( INDEX( param_list_and_type!$F:$K, MATCH(1, (param_list_and_type!$A:$A=A14)* (param_list_and_type!$B:$B=B14)* (param_list_and_type!$C:$C=C14), 0), MATCH(E14, param_list_and_type!$F$1:$K$1, 0) )="X", "Yes", "No" )} -> Yes
A15: TREATMENT | B15: art_cont | C15: dsd | D15: DSD (differentiated service delivery) | E15: infant_inf | F15: {=IF( INDEX( param_list_and_type!$F:$K, MATCH(1, (param_list_and_type!$A:$A=A15)* (param_list_and_type!$B:$B=B15)* (param_list_and_type!$C:$C=C15), 0), MATCH(E15, param_list_and_type!$F$1:$K$1, 0) )="X", "Yes", "No" )} -> No | G15: 0
A16: TREATMENT | B16: art_cont | C16: dsd | D16: DSD (differentiated service delivery) | E16: first_90 | F16: {=IF( INDEX( param_list_and_type!$F:$K, MATCH(1, (param_list_and_type!$A:$A=A16)* (param_list_and_type!$B:$B=B16)* (param_list_and_type!$C:$C=C16), 0), MATCH(E16, param_list_and_type!$F$1:$K$1, 0) )="X", "Yes", "No" )} -> No | G16: 0
A17: TREATMENT | B17: art_cont | C17: dsd | D17: DSD (differentiated service delivery) | E17: sec_90 | F17: {=IF( INDEX( param_list_and_type!$F:$K, MATCH(1, (param_list_and_type!$A:$A=A17)* (param_list_and_type!$B:$B=B17)* (param_list_and_type!$C:$C=C17), 0), MATCH(E17, param_list_and_type!$F$1:$K$1, 0) )="X", "Yes", "No" )} -> Yes
A18: TREATMENT | B18: art_cont | C18: dsd | D18: DSD (differentiated service delivery) | E18: third_90 | F18: {=IF( INDEX( param_list_and_type!$F:$K, MATCH(1, (param_list_and_type!$A:$A=A18)* (param_list_and_type!$B:$B=B18)* (param_list_and_type!$C:$C=C18), 0), MATCH(E18, param_list_and_type!$F$1:$K$1, 0) )="X", "Yes", "No" )} -> Yes
A19: TREATMENT | B19: art_cont | C19: dsd | D19: DSD (differentiated service delivery) | E19: deaths | F19: {=IF( INDEX( param_list_and_type!$F:$K, MATCH(1, (param_list_and_type!$A:$A=A19)* (param_list_and_type!$B:$B=B19)* (param_list_and_type!$C:$C=C19), 0), MATCH(E19, param_list_and_type!$F$1:$K$1, 0) )="X", "Yes", "No" )} -> No | G19: 0
A20: TREATMENT | B20: oi_prophylaxis | C20: cotrim | D20: Cotrimoxazole prophylaxis | E20: adult_inf | F20: {=IF( INDEX( param_list_and_type!$F:$K, MATCH(1, (param_list_and_type!$A:$A=A20)* (param_list_and_type!$B:$B=B20)* (param_list_and_type!$C:$C=C20), 0), MATCH(E20, param_list_and_type!$F$1:$K$1, 0) )="X", "Yes", "No" )} -> No | G20: 0
A21: TREATMENT | B21: oi_prophylaxis | C21: cotrim | D21: Cotrimoxazole prophylaxis | E21: infant_inf | F21: {=IF( INDEX( param_list_and_type!$F:$K, MATCH(1, (param_list_and_type!$A:$A=A21)* (param_list_and_type!$B:$B=B21)* (param_list_and_type!$C:$C=C21), 0), MATCH(E21, param_list_and_type!$F$1:$K$1, 0) )="X", "Yes", "No" )} -> No | G21: 0
A22: TREATMENT | B22: oi_prophylaxis | C22: cotrim | D22: Cotrimoxazole prophylaxis | E22: first_90 | F22: {=IF( INDEX( param_list_and_type!$F:$K, MATCH(1, (param_list_and_type!$A:$A=A22)* (param_list_and_type!$B:$B=B22)* (param_list_and_type!$C:$C=C22), 0), MATCH(E22, param_list_and_type!$F$1:$K$1, 0) )="X", "Yes", "No" )} -> No | G22: 0
A23: TREATMENT | B23: oi_prophylaxis | C23: cotrim | D23: Cotrimoxazole prophylaxis | E23: sec_90 | F23: {=IF( INDEX( param_list_and_type!$F:$K, MATCH(1, (param_list_and_type!$A:$A=A23)* (param_list_and_type!$B:$B=B23)* (param_list_and_type!$C:$C=C23), 0), MATCH(E23, param_list_and_type!$F$1:$K$1, 0) )="X", "Yes", "No" )} -> No | G23: 0
A24: TREATMENT | B24: oi_prophylaxis | C24: cotrim | D24: Cotrimoxazole prophylaxis | E24: third_90 | F24: {=IF( INDEX( param_list_and_type!$F:$K, MATCH(1, (param_list_and_type!$A:$A=A24)* (param_list_and_type!$B:$B=B24)* (param_list_and_type!$C:$C=C24), 0), MATCH(E24, param_list_and_type!$F$1:$K$1, 0) )="X", "Yes", "No" )} -> No | G24: 0
A25: TREATMENT | B25: oi_prophylaxis | C25: cotrim | D25: Cotrimoxazole prophylaxis | E25: deaths | F25: {=IF( INDEX( param_list_and_type!$F:$K, MATCH(1, (param_list_and_type!$A:$A=A25)* (param_list_and_type!$B:$B=B25)* (param_list_and_type!$C:$C=C25), 0), MATCH(E25, param_list_and_type!$F$1:$K$1, 0) )="X", "Yes", "No" )} -> Yes
A26: TREATMENT | B26: art_init | C26: art_init | D26: ART initiation (and re-initiation) | E26: adult_inf | F26: {=IF( INDEX( param_list_and_type!$F:$K, MATCH(1, (param_list_and_type!$A:$A=A26)* (param_list_and_type!$B:$B=B26)* (param_list_and_type!$C:$C=C26), 0), MATCH(E26, param_list_and_type!$F$1:$K$1, 0) )="X", "Yes", "No" )} -> Yes
A27: TREATMENT | B27: art_init | C27: art_init | D27: ART initiation (and re-initiation) | E27: infant_inf | F27: {=IF( INDEX( param_list_and_type!$F:$K, MATCH(1, (param_list_and_type!$A:$A=A27)* (param_list_and_type!$B:$B=B27)* (param_list_and_type!$C:$C=C27), 0), MATCH(E27, param_list_and_type!$F$1:$K$1, 0) )="X", "Yes", "No" )} -> Yes
A28: TREATMENT | B28: art_init | C28: art_init | D28: ART initiation (and re-initiation) | E28: first_90 | F28: {=IF( INDEX( param_list_and_type!$F:$K, MATCH(1, (param_list_and_type!$A:$A=A28)* (param_list_and_type!$B:$B=B28)* (param_list_and_type!$C:$C=C28), 0), MATCH(E28, param_list_and_type!$F$1:$K$1, 0) )="X", "Yes", "No" )} -> No | G28: 0
A29: TREATMENT | B29: art_init | C29: art_init | D29: ART initiation (and re-initiation) | E29: sec_90 | F29: {=IF( INDEX( param_list_and_type!$F:$K, MATCH(1, (param_list_and_type!$A:$A=A29)* (param_list_and_type!$B:$B=B29)* (param_list_and_type!$C:$C=C29), 0), MATCH(E29, param_list_and_type!$F$1:$K$1, 0) )="X", "Yes", "No" )} -> Yes
A30: TREATMENT | B30: art_init | C30: art_init | D30: ART initiation (and re-initiation) | E30: third_90 | F30: {=IF( INDEX( param_list_and_type!$F:$K, MATCH(1, (param_list_and_type!$A:$A=A30)* (param_list_and_type!$B:$B=B30)* (param_list_and_type!$C:$C=C30), 0), MATCH(E30, param_list_and_type!$F$1:$K$1, 0) )="X", "Yes", "No" )} -> Yes
A31: TREATMENT | B31: art_init | C31: art_init | D31: ART initiation (and re-initiation) | E31: deaths | F31: {=IF( INDEX( param_list_and_type!$F:$K, MATCH(1, (param_list_and_type!$A:$A=A31)* (param_list_and_type!$B:$B=B31)* (param_list_and_type!$C:$C=C31), 0), MATCH(E31, param_list_and_type!$F$1:$K$1, 0) )="X", "Yes", "No" )} -> Yes
A32: TREATMENT | B32: vl_monitoring | C32: vl_targeted | D32: VL monitoring: suspected failure | E32: adult_inf | F32: {=IF( INDEX( param_list_and_type!$F:$K, MATCH(1, (param_list_and_type!$A:$A=A32)* (param_list_and_type!$B:$B=B32)* (param_list_and_type!$C:$C=C32), 0), MATCH(E32, param_list_and_type!$F$1:$K$1, 0) )="X", "Yes", "No" )} -> No | G32: 0
A33: TREATMENT | B33: vl_monitoring | C33: vl_targeted | D33: VL monitoring: suspected failure | E33: infant_inf | F33: {=IF( INDEX( param_list_and_type!$F:$K, MATCH(1, (param_list_and_type!$A:$A=A33)* (param_list_and_type!$B:$B=B33)* (param_list_and_type!$C:$C=C33), 0), MATCH(E33, param_list_and_type!$F$1:$K$1, 0) )="X", "Yes", "No" )} -> No | G33: 0
A34: TREATMENT | B34: vl_monitoring | C34: vl_targeted | D34: VL monitoring: suspected failure | E34: first_90 | F34: {=IF( INDEX( param_list_and_type!$F:$K, MATCH(1, (param_list_and_type!$A:$A=A34)* (param_list_and_type!$B:$B=B34)* (param_list_and_type!$C:$C=C34), 0), MATCH(E34, param_list_and_type!$F$1:$K$1, 0) )="X", "Yes", "No" )} -> No | G34: 0
A35: TREATMENT | B35: vl_monitoring | C35: vl_targeted | D35: VL monitoring: suspected failure | E35: sec_90 | F35: {=IF( INDEX( param_list_and_type!$F:$K, MATCH(1, (param_list_and_type!$A:$A=A35)* (param_list_and_type!$B:$B=B35)* (param_list_and_type!$C:$C=C35), 0), MATCH(E35, param_list_and_type!$F$1:$K$1, 0) )="X", "Yes", "No" )} -> No | G35: 0
A36: TREATMENT | B36: vl_monitoring | C36: vl_targeted | D36: VL monitoring: suspected failure | E36: third_90 | F36: {=IF( INDEX( param_list_and_type!$F:$K, MATCH(1, (param_list_and_type!$A:$A=A36)* (param_list_and_type!$B:$B=B36)* (param_list_and_type!$C:$C=C36), 0), MATCH(E36, param_list_and_type!$F$1:$K$1, 0) )="X", "Yes", "No" )} -> Yes
A37: TREATMENT | B37: vl_monitoring | C37: vl_targeted | D37: VL monitoring: suspected failure | E37: deaths | F37: {=IF( INDEX( param_list_and_type!$F:$K, MATCH(1, (param_list_and_type!$A:$A=A37)* (param_list_and_type!$B:$B=B37)* (param_list_and_type!$C:$C=C37), 0), MATCH(E37, param_list_and_type!$F$1:$K$1, 0) )="X", "Yes", "No" )} -> No | G37: 0
A38: TREATMENT | B38: vl_monitoring | C38: vl_routine | D38: Routine VL monitoring | E38: adult_inf | F38: {=IF( INDEX( param_list_and_type!$F:$K, MATCH(1, (param_list_and_type!$A:$A=A38)* (param_list_and_type!$B:$B=B38)* (param_list_and_type!$C:$C=C38), 0), MATCH(E38, param_list_and_type!$F$1:$K$1, 0) )="X", "Yes", "No" )} -> No | G38: 0
A39: TREATMENT | B39: vl_monitoring | C39: vl_routine | D39: Routine VL monitoring | E39: infant_inf | F39: {=IF( INDEX( param_list_and_type!$F:$K, MATCH(1, (param_list_and_type!$A:$A=A39)* (param_list_and_type!$B:$B=B39)* (param_list_and_type!$C:$C=C39), 0), MATCH(E39, param_list_and_type!$F$1:$K$1, 0) )="X", "Yes", "No" )} -> No | G39: 0
A40: TREATMENT | B40: vl_monitoring | C40: vl_routine | D40: Routine VL monitoring | E40: first_90 | F40: {=IF( INDEX( param_list_and_type!$F:$K, MATCH(1, (param_list_and_type!$A:$A=A40)* (param_list_and_type!$B:$B=B40)* (param_list_and_type!$C:$C=C40), 0), MATCH(E40, param_list_and_type!$F$1:$K$1, 0) )="X", "Yes", "No" )} -> No | G40: 0
...

Sheet other_key_values
A1: hiv_mortality_not_on_art
A2: hiv_mortality_on_art
A3: hiv_mortality_VS
A4: hiv_mortality_not_vs
A5: mtct_rate_on_art | B5: 15-45% | C5: https://www.who.int/teams/global-hiv-hepatitis-and-stis-programmes/hiv/prevention/mother-to-child-transmission-of-hiv
A6: mtct_rate_not_on_art | B6: <5% | C6: https://www.unaids.org/sites/default/files/media_asset/FactSheet_Children_en.pdf
A7: TB mortality without treatment
A25: =630000/40800000 -> 0.015441176

Sheet params_cost
A1: area | B1: component | C1: id | D1: label | E1: unit_cost | F1: source
A2: TREATMENT | B2: art_cont | C2: art_provision | D2: ART provision for all
A3: TREATMENT | B3: art_cont | C3: mmd | D3: MMD (multi-month dispensing)
A4: TREATMENT | B4: art_cont | C4: dsd | D4: DSD (differentiated service delivery)
A5: TREATMENT | B5: oi_prophylaxis | C5: cotrim | D5: Cotrimoxazole prophylaxis
A6: TREATMENT | B6: art_init | C6: art_init | D6: ART initiation (and re-initiation)
A7: TREATMENT | B7: vl_monitoring | C7: vl_targeted | D7: VL monitoring: suspected failure
A8: TREATMENT | B8: vl_monitoring | C8: vl_routine | D8: Routine VL monitoring
A9: TREATMENT | B9: oi_managment | C9: oi_tb_test | D9: OI: TB testing for symptomatic
A10: TREATMENT | B10: oi_managment | C10: oi_tb_tpt | D10: OI: TB preventive therapy (TPT)
A11: TREATMENT | B11: oi_managment | C11: oi_tb_tx | D11: OI: TB treatment
A12: TREATMENT | B12: oi_managment | C12: oi_crypto_tx | D12: OI: Cryptococcal treatment
A13: TREATMENT | B13: ahd | C13: ahd_lam | D13: AHD: LAM for Stage 3/4 / seriously ill
... A32: PREVENTION | B32: vmmc | C32: vmmc | D32: VMMC
A33: ANC | B33: anc_hiv_test | D33: ANC: HIV testing
A34: ANC | B34: eID | D34: EID (early infant diagnosis)
A35: ANC | B35: anc_vl_testing | D35: ANC: Viral Load Testing
