Workbook
Name _Key1: #REF!
Name _Order1: 255
Name _Sort: #REF!
Name All_Outpatients_diagnosed: '[1]Summary people'!$S$20
Name Ambulanciers_per_bed: '[1]Staff&infrastructure assumption'!$C$14
Name ARTcoverage: #REF!
Name asymp_rate: [2]Summary!$H$3
Name Av_days_month: '[3]Setting 1 Costs'!$B$9
Name Beds_occupied: '[3]Setting 1 Costs'!$B$8
Name BedStay_Critical: '[1]Patient & case assumptions'!$C$17
Name BedStay_Severe: '[1]Patient & case assumptions'!$C$16
Name Buffer_stock: '[4]Model Assumption'!$E$127
Name Caretaker_to_outpatient: '[1]Patient & case assumptions'!$C$24
Name Caretakers_per_bed: '[1]Staff&infrastructure assumption'!$C$13
Name COST_METHOD: #REF!
Name CostYear: [5]Inflation!$B$1
Name CostYear: Inflation!$B$1
Name CostYrr: Inflation!$B$1
Name CovLev: #REF!
Name cpap: [2]Selection!$D$37
Name cpap_cost: '[2]Cost inputs'!$F$38
Name cpap_cov: [2]Selection!$G$37
Name CriticalCasePercentage: '[1]Patient & case assumptions'!$C$13
Name cur_1: [6]Start!$C$22
Name currency: [7]Assumptions!$O$9
Name CURRENCY: #REF!
Name Current_OutBreak_Week_Number: '[1]Total forecast by item'!$E$14
Name CurrResults: #REF!
Name CurrYear: [8]Projection!$E$6
Name CutOffMaxTests: '[1]Patient & case assumptions'!$C$29
Name d: [9]Sheet5!$A:$C
Name DataDate: [10]OfDates!$B$2
Name DataWuenic: [10]OfDates!$B$4
Name DataYear: [10]OfDates!$B$6
Name date: Title!$M$5
Name DDL_Private: [11]drop_down_lists!$G$60:$G$63
Name DDL_yes_no_NR_ND: [11]drop_down_lists!$F$33:$F$36
Name Depr_Category: [12]!depreciation[Category]
Name DHIS_HCavg: '[5]ART PPP'!$C$18
Name DHIS_HCavg: 'ART PPP'!$C$18
Name Discount_Rate: '[12]Model parameters'!$B$8
Name DoublingTime_Best: '[1]Epi curve calcs'!$Q$13
Name DoublingTime_Medium: '[1]Epi curve calcs'!$J$13
Name DoublingTime_Worst: '[1]Epi curve calcs'!$C$13
Name drug_costs: '[2]Cost inputs'!$B$117:$F$125
Name Epi_drop_rate: '[4]Model Assumption'!$E$133
Name Epi_Growth_rate: '[4]Model Assumption'!$E$132
Name Equipment_usage_table: '[1]Equipment per person per day'!$D$14:$I$105
Name ex_rate_2017: [13]Inflation!$F$21
Name exr: [13]SummaryInterventions!$A$27
Name exrate: [5]ZARtoUSD!$F$5
Name exrate: '[13]ZAR-USD'!$E$7
Name exrate: ZARtoUSD!$F$5
Name Fast_doubling_rate: '[1]Epi curve assumptions'!$C$16
Name Filename: [14]drop_down_lists!$H$3
Name HCW_per_lab: '[1]Staff&infrastructure assumption'!$C$28
Name HCWs_per_bed: '[1]Staff&infrastructure assumption'!$C$11
Name hfnc: [2]Selection!$D$34
Name hfnc_cost: '[2]Cost inputs'!$F$45
Name hfnc_cov: [2]Selection!$G$34

Sheet Title
M5: Version 10.1, 1 Apr 2025
L34: Lise Jamieson, Khumo Modiba, Gesine Meyer-Rath
M35: Queries: gesine@bu.edu
K41: Suggested citation:
K42: Jamieson L, Modiba K, Meyer-Rath G (2024) National HIV Unit Cost Model, South Africa. Health Economics and Epidemiology Research Office, University of the Witwatersrand, Johannesburg.

Sheet Summary of unit costs
A1: Intervention | C1: Population/notes | D1: Est population size (Thembisa 4.7+) | E1: Costing method | F1: Programme Area | G1: Unit Cost (2024 ZAR) | H1: Unit cost (2024 USD) | I1: Unit | J1: Validate % columns | K1: Consumables | L1: Drugs | M1: Equipment | N1: Lab Tests | O1: Overheads | P1: Staff | Q1: Consumables | R1: Drugs | S1: Equipment | T1: Lab Tests | U1: Overheads | V1: Staff
A2: ART Adults (1st line 1st year) | C2: ART adults starting ART on first line in given year | D2: 208375.3 | E2: Ingredients | F2: ART | G2: {=IF(E2="Literature",INDEX(LiteratureCost!$I$2:$I$10,MATCH('Summary of unit costs'!A2,LiteratureCost!$A$2:$A$10,0)),INDEX(InterventionCosts!$L$1:$L$2363,MATCH(A2,IF(InterventionCosts!$F$1:$F$2363="Cost per intervention",InterventionCosts!$A$1:$A$2363),0)))} -> 5352.6248 | H2: =G2/exrate -> 286.84009 | I2: {=IF(E2="Literature",INDEX(LiteratureCost!$G$2:$G$22,MATCH('Summary of unit costs'!A2,LiteratureCost!$A$2:$A$22,0)),INDEX(InterventionCosts!$L$1:$L$3432,MATCH(A2,IF(InterventionCosts!$F$1:$F$3432="Unit",InterventionCosts!$A$1:$A$3432),0)))} -> per person per year | J2: =G2/SUM(Q2:V2) -> 1 | K2: =Q2/$G2 -> 0 | L2: =R2/$G2 -> 0.24332172 | M2: =S2/$G2 -> 0 | N2: =T2/$G2 -> 0.21593891 | O2: =U2/$G2 -> 0.12432272 | P2: =V2/$G2 -> 0.41641666 | Q2: =SUMIFS(InterventionCosts!$K$2:$K$3432,InterventionCosts!$D$2:$D$3432,'Summary of unit costs'!Q$1,InterventionCosts!$A$2:$A$3432,'Summary of unit costs'!$A2) -> 0 | R2: =SUMIFS(InterventionCosts!$K$2:$K$3432,InterventionCosts!$D$2:$D$3432,'Summary of unit costs'!R$1,InterventionCosts!$A$2:$A$3432,'Summary of unit costs'!$A2) -> 1302.4098 | S2: =SUMIFS(InterventionCosts!$K$2:$K$3432,InterventionCosts!$D$2:$D$3432,'Summary of unit costs'!S$1,InterventionCosts!$A$2:$A$3432,'Summary of unit costs'!$A2) -> 0 | T2: =SUMIFS(InterventionCosts!$K$2:$K$3432,InterventionCosts!$D$2:$D$3432,'Summary of unit costs'!T$1,InterventionCosts!$A$2:$A$3432,'Summary of unit costs'!$A2) -> 1155.84 | U2: =SUMIFS(InterventionCosts!$K$2:$K$3432,InterventionCosts!$D$2:$D$3432,'Summary of unit costs'!U$1,InterventionCosts!$A$2:$A$3432,'Summary of unit costs'!$A2) -> 665.45285 | V2: =SUMIFS(InterventionCosts!$K$2:$K$3432,InterventionCosts!$D$2:$D$3432,'Summary of unit costs'!V$1,InterventionCosts!$A$2:$A$3432,'Summary of unit costs'!$A2) -> 2228.9221
A3: ART Adults (1st line followup) | C3: ART adults in years following starting ART | D3: =5761850-D2 -> 5553474.7 | E3: Ingredients | F3: ART | G3: {=IF(E3="Literature",INDEX(LiteratureCost!$I$2:$I$10,MATCH('Summary of unit costs'!A3,LiteratureCost!$A$2:$A$10,0)),INDEX(InterventionCosts!$L$1:$L$2363,MATCH(A3,IF(InterventionCosts!$F$1:$F$2363="Cost per intervention",InterventionCosts!$A$1:$A$2363),0)))} -> 3346.5773 | H3: =G3/exrate -> 179.33865 | I3: {=IF(E3="Literature",INDEX(LiteratureCost!$G$2:$G$22,MATCH('Summary of unit costs'!A3,LiteratureCost!$A$2:$A$22,0)),INDEX(InterventionCosts!$L$1:$L$3432,MATCH(A3,IF(InterventionCosts!$F$1:$F$3432="Unit",InterventionCosts!$A$1:$A$3432),0)))} -> per person per year | J3: =G3/SUM(Q3:V3) -> 1 | K3: =Q3/$G3 -> 0 | L3: =R3/$G3 -> 0.35555273 | M3: =S3/$G3 -> 0 | N3: =T3/$G3 -> 0.18562702 | O3: =U3/$G3 -> 0.10548849 | P3: =V3/$G3 -> 0.35333176 | Q3: =SUMIFS(InterventionCosts!$K$2:$K$3432,InterventionCosts!$D$2:$D$3432,'Summary of unit costs'!Q$1,InterventionCosts!$A$2:$A$3432,'Summary of unit costs'!$A3) -> 0 | R3: =SUMIFS(InterventionCosts!$K$2:$K$3432,InterventionCosts!$D$2:$D$3432,'Summary of unit costs'!R$1,InterventionCosts!$A$2:$A$3432,'Summary of unit costs'!$A3) -> 1189.8847 | S3: =SUMIFS(InterventionCosts!$K$2:$K$3432,InterventionCosts!$D$2:$D$3432,'Summary of unit costs'!S$1,InterventionCosts!$A$2:$A$3432,'Summary of unit costs'!$A3) -> 0 | T3: =SUMIFS(InterventionCosts!$K$2:$K$3432,InterventionCosts!$D$2:$D$3432,'Summary of unit costs'!T$1,InterventionCosts!$A$2:$A$3432,'Summary of unit costs'!$A3) -> 621.21516 | U3: =SUMIFS(InterventionCosts!$K$2:$K$3432,InterventionCosts!$D$2:$D$3432,'Summary of unit costs'!U$1,InterventionCosts!$A$2:$A$3432,'Summary of unit costs'!$A3) -> 353.02539 | V3: =SUMIFS(InterventionCosts!$K$2:$K$3432,InterventionCosts!$D$2:$D$3432,'Summary of unit costs'!V$1,InterventionCosts!$A$2:$A$3432,'Summary of unit costs'!$A3) -> 1182.452
A4: ART Adults (2nd line followup) | C4: ART adults on second line ART | D4: 577009 | E4: Ingredients | F4: ART | G4: {=IF(E4="Literature",INDEX(LiteratureCost!$I$2:$I$10,MATCH('Summary of unit costs'!A4,LiteratureCost!$A$2:$A$10,0)),INDEX(InterventionCosts!$L$1:$L$2363,MATCH(A4,IF(InterventionCosts!$F$1:$F$2363="Cost per intervention",InterventionCosts!$A$1:$A$2363),0)))} -> 5882.5211 | H4: =G4/exrate -> 315.23653 | I4: {=IF(E4="Literature",INDEX(LiteratureCost!$G$2:$G$22,MATCH('Summary of unit costs'!A4,LiteratureCost!$A$2:$A$22,0)),INDEX(InterventionCosts!$L$1:$L$3432,MATCH(A4,IF(InterventionCosts!$F$1:$F$3432="Unit",InterventionCosts!$A$1:$A$3432),0)))} -> per person per year | J4: =G4/SUM(Q4:V4) -> 1 | K4: =Q4/$G4 -> 0 | L4: =R4/$G4 -> 0.48395472 | M4: =S4/$G4 -> 0 | N4: =T4/$G4 -> 0.18976566 | O4: =U4/$G4 -> 0.07501575 | P4: =V4/$G4 -> 0.25126388 | Q4: =SUMIFS(InterventionCosts!$K$2:$K$3432,InterventionCosts!$D$2:$D$3432,'Summary of unit costs'!Q$1,InterventionCosts!$A$2:$A$3432,'Summary of unit costs'!$A4) -> 0 | R4: =SUMIFS(InterventionCosts!$K$2:$K$3432,InterventionCosts!$D$2:$D$3432,'Summary of unit costs'!R$1,InterventionCosts!$A$2:$A$3432,'Summary of unit costs'!$A4) -> 2846.8739 | S4: =SUMIFS(InterventionCosts!$K$2:$K$3432,InterventionCosts!$D$2:$D$3432,'Summary of unit costs'!S$1,InterventionCosts!$A$2:$A$3432,'Summary of unit costs'!$A4) -> 0 | T4: =SUMIFS(InterventionCosts!$K$2:$K$3432,InterventionCosts!$D$2:$D$3432,'Summary of unit costs'!T$1,InterventionCosts!$A$2:$A$3432,'Summary of unit costs'!$A4) -> 1116.3005 | U4: =SUMIFS(InterventionCosts!$K$2:$K$3432,InterventionCosts!$D$2:$D$3432,'Summary of unit costs'!U$1,InterventionCosts!$A$2:$A$3432,'Summary of unit costs'!$A4) -> 441.28173 | V4: =SUMIFS(InterventionCosts!$K$2:$K$3432,InterventionCosts!$D$2:$D$3432,'Summary of unit costs'!V$1,InterventionCosts!$A$2:$A$3432,'Summary of unit costs'!$A4) -> 1478.0651
A5: ART adult (average cost) | C5: Average cost estimate of above, weighted by est. population size | E5: Ingredients | F5: ART | G5: =SUMPRODUCT(G2:G4,$D$2:$D$4)/SUM($D$2:$D$4) -> 3643.3615 | H5: =G5/exrate -> 195.24293 | I5: per person per year | J5: =G5/SUM(Q5:V5) -> 1 | K5: =Q5/$G5 -> 0 | L5: =R5/$G5 -> 0.36900398 | M5: =S5/$G5 -> 0 | N5: =T5/$G5 -> 0.18769918 | O5: =U5/$G5 -> 0.10191946 | P5: =V5/$G5 -> 0.34137737 | Q5: =SUMPRODUCT(Q2:Q4,$D$2:$D$4)/SUM($D$2:$D$4) -> 0 | R5: =SUMPRODUCT(R2:R4,$D$2:$D$4)/SUM($D$2:$D$4) -> 1344.4149 | S5: =SUMPRODUCT(S2:S4,$D$2:$D$4)/SUM($D$2:$D$4) -> 0 | T5: =SUMPRODUCT(T2:T4,$D$2:$D$4)/SUM($D$2:$D$4) -> 683.85598 | U5: =SUMPRODUCT(U2:U4,$D$2:$D$4)/SUM($D$2:$D$4) -> 371.32945 | V5: =SUMPRODUCT(V2:V4,$D$2:$D$4)/SUM($D$2:$D$4) -> 1243.7612
A6: ART Paeds Neonates | C6: Paediatric ART, first month of birth (as per ART guidelines) | E6: Ingredients | F6: ART | G6: {=IF(E6="Literature",INDEX(LiteratureCost!$I$2:$I$10,MATCH('Summary of unit costs'!A6,LiteratureCost!$A$2:$A$10,0)),INDEX(InterventionCosts!$L$1:$L$2363,MATCH(A6,IF(InterventionCosts!$F$1:$F$2363="Cost per intervention",InterventionCosts!$A$1:$A$2363),0)))} -> 1770.7362 | H6: =G6/exrate -> 94.891411 | I6: {=IF(E6="Literature",INDEX(LiteratureCost!$G$2:$G$22,MATCH('Summary of unit costs'!A6,LiteratureCost!$A$2:$A$22,0)),INDEX(InterventionCosts!$L$1:$L$3432,MATCH(A6,IF(InterventionCosts!$F$1:$F$3432="Unit",InterventionCosts!$A$1:$A$3432),0)))} -> per person per year | J6: =G6/SUM(Q6:V6) -> 1 | K6: =Q6/$G6 -> 0 | L6: =R6/$G6 -> 0.021150751 | M6: =S6/$G6 -> 0 | N6: =T6/$G6 -> 0.32849371 | O6: =U6/$G6 -> 0.14952484 | P6: =V6/$G6 -> 0.5008307 | Q6: =SUMIFS(InterventionCosts!$K$2:$K$3432,InterventionCosts!$D$2:$D$3432,'Summary of unit costs'!Q$1,InterventionCosts!$A$2:$A$3432,'Summary of unit costs'!$A6) -> 0 | R6: =SUMIFS(InterventionCosts!$K$2:$K$3432,InterventionCosts!$D$2:$D$3432,'Summary of unit costs'!R$1,InterventionCosts!$A$2:$A$3432,'Summary of unit costs'!$A6) -> 37.4524 | S6: =SUMIFS(InterventionCosts!$K$2:$K$3432,InterventionCosts!$D$2:$D$3432,'Summary of unit costs'!S$1,InterventionCosts!$A$2:$A$3432,'Summary of unit costs'!$A6) -> 0 | T6: =SUMIFS(InterventionCosts!$K$2:$K$3432,InterventionCosts!$D$2:$D$3432,'Summary of unit costs'!T$1,InterventionCosts!$A$2:$A$3432,'Summary of unit costs'!$A6) -> 581.67569 | U6: =SUMIFS(InterventionCosts!$K$2:$K$3432,InterventionCosts!$D$2:$D$3432,'Summary of unit costs'!U$1,InterventionCosts!$A$2:$A$3432,'Summary of unit costs'!$A6) -> 264.76904 | V6: =SUMIFS(InterventionCosts!$K$2:$K$3432,InterventionCosts!$D$2:$D$3432,'Summary of unit costs'!V$1,InterventionCosts!$A$2:$A$3432,'Summary of unit costs'!$A6) -> 886.83903
A7: ART Paeds Kids <1 | C7: Paediatric ART in first year of life (after first month) | D7: 702 | E7: Ingredients | F7: ART | G7: {=IF(E7="Literature",INDEX(LiteratureCost!$I$2:$I$10,MATCH('Summary of unit costs'!A7,LiteratureCost!$A$2:$A$10,0)),INDEX(InterventionCosts!$L$1:$L$2363,MATCH(A7,IF(InterventionCosts!$F$1:$F$2363="Cost per intervention",InterventionCosts!$A$1:$A$2363),0)))} -> 5584.3168 | H7: =G7/exrate -> 299.25616 | I7: {=IF(E7="Literature",INDEX(LiteratureCost!$G$2:$G$22,MATCH('Summary of unit costs'!A7,LiteratureCost!$A$2:$A$22,0)),INDEX(InterventionCosts!$L$1:$L$3432,MATCH(A7,IF(InterventionCosts!$F$1:$F$3432="Unit",InterventionCosts!$A$1:$A$3432),0)))} -> per person per year | J7: =G7/SUM(Q7:V7) -> 1 | K7: =Q7/$G7 -> 0 | L7: =R7/$G7 -> 0.37753341 | M7: =S7/$G7 -> 0 | N7: =T7/$G7 -> 0.10416237 | O7: =U7/$G7 -> 0.1191646 | P7: =V7/$G7 -> 0.39913962 | Q7: =SUMIFS(InterventionCosts!$K$2:$K$3432,InterventionCosts!$D$2:$D$3432,'Summary of unit costs'!Q$1,InterventionCosts!$A$2:$A$3432,'Summary of unit costs'!$A7) -> 0 | R7: =SUMIFS(InterventionCosts!$K$2:$K$3432,InterventionCosts!$D$2:$D$3432,'Summary of unit costs'!R$1,InterventionCosts!$A$2:$A$3432,'Summary of unit costs'!$A7) -> 2108.2662 | S7: =SUMIFS(InterventionCosts!$K$2:$K$3432,InterventionCosts!$D$2:$D$3432,'Summary of unit costs'!S$1,InterventionCosts!$A$2:$A$3432,'Summary of unit costs'!$A7) -> 0 | T7: =SUMIFS(InterventionCosts!$K$2:$K$3432,InterventionCosts!$D$2:$D$3432,'Summary of unit costs'!T$1,InterventionCosts!$A$2:$A$3432,'Summary of unit costs'!$A7) -> 581.67569 | U7: =SUMIFS(InterventionCosts!$K$2:$K$3432,InterventionCosts!$D$2:$D$3432,'Summary of unit costs'!U$1,InterventionCosts!$A$2:$A$3432,'Summary of unit costs'!$A7) -> 665.45285 | V7: =SUMIFS(InterventionCosts!$K$2:$K$3432,InterventionCosts!$D$2:$D$3432,'Summary of unit costs'!V$1,InterventionCosts!$A$2:$A$3432,'Summary of unit costs'!$A7) -> 2228.9221
A8: ART Paeds Kids 1-2 (1st year) | C8: Peadiatric ART, starting ART at ages 1-2 yrs | D8: 397 | E8: Ingredients | F8: ART | G8: {=IF(E8="Literature",INDEX(LiteratureCost!$I$2:$I$10,MATCH('Summary of unit costs'!A8,LiteratureCost!$A$2:$A$10,0)),INDEX(InterventionCosts!$L$1:$L$2363,MATCH(A8,IF(InterventionCosts!$F$1:$F$2363="Cost per intervention",InterventionCosts!$A$1:$A$2363),0)))} -> 7995.96 | H8: =G8/exrate -> 428.49293 | I8: {=IF(E8="Literature",INDEX(LiteratureCost!$G$2:$G$22,MATCH('Summary of unit costs'!A8,LiteratureCost!$A$2:$A$22,0)),INDEX(InterventionCosts!$L$1:$L$3432,MATCH(A8,IF(InterventionCosts!$F$1:$F$3432="Unit",InterventionCosts!$A$1:$A$3432),0)))} -> per person per year | J8: =G8/SUM(Q8:V8) -> 1 | K8: =Q8/$G8 -> 0 | L8: =R8/$G8 -> 0.5033572 | M8: =S8/$G8 -> 0 | N8: =T8/$G8 -> 0.13466313 | O8: =U8/$G8 -> 0.083223635 | P8: =V8/$G8 -> 0.27875603 | Q8: =SUMIFS(InterventionCosts!$K$2:$K$3432,InterventionCosts!$D$2:$D$3432,'Summary of unit costs'!Q$1,InterventionCosts!$A$2:$A$3432,'Summary of unit costs'!$A8) -> 0 | R8: =SUMIFS(InterventionCosts!$K$2:$K$3432,InterventionCosts!$D$2:$D$3432,'Summary of unit costs'!R$1,InterventionCosts!$A$2:$A$3432,'Summary of unit costs'!$A8) -> 4024.824 | S8: =SUMIFS(InterventionCosts!$K$2:$K$3432,InterventionCosts!$D$2:$D$3432,'Summary of unit costs'!S$1,InterventionCosts!$A$2:$A$3432,'Summary of unit costs'!$A8) -> 0 | T8: =SUMIFS(InterventionCosts!$K$2:$K$3432,InterventionCosts!$D$2:$D$3432,'Summary of unit costs'!T$1,InterventionCosts!$A$2:$A$3432,'Summary of unit costs'!$A8) -> 1076.761 | U8: =SUMIFS(InterventionCosts!$K$2:$K$3432,InterventionCosts!$D$2:$D$3432,'Summary of unit costs'!U$1,InterventionCosts!$A$2:$A$3432,'Summary of unit costs'!$A8) -> 665.45285 | V8: =SUMIFS(InterventionCosts!$K$2:$K$3432,InterventionCosts!$D$2:$D$3432,'Summary of unit costs'!V$1,InterventionCosts!$A$2:$A$3432,'Summary of unit costs'!$A8) -> 2228.9221
A9: ART Paeds Kids 1-2 (followup) | C9: Peadiatric ART, in year after initiation at ages 1-2 yrs | D9: 2795 | E9: Ingredients | F9: ART | G9: {=IF(E9="Literature",INDEX(LiteratureCost!$I$2:$I$10,MATCH('Summary of unit costs'!A9,LiteratureCost!$A$2:$A$10,0)),INDEX(InterventionCosts!$L$1:$L$2363,MATCH(A9,IF(InterventionCosts!$F$1:$F$2363="Cost per intervention",InterventionCosts!$A$1:$A$2363),0)))} -> 6141.9771 | H9: =G9/exrate -> 329.14044 | I9: {=IF(E9="Literature",INDEX(LiteratureCost!$G$2:$G$22,MATCH('Summary of unit costs'!A9,LiteratureCost!$A$2:$A$22,0)),INDEX(InterventionCosts!$L$1:$L$3432,MATCH(A9,IF(InterventionCosts!$F$1:$F$3432="Unit",InterventionCosts!$A$1:$A$3432),0)))} -> per person per year | J9: =G9/SUM(Q9:V9) -> 1 | K9: =Q9/$G9 -> 0 | L9: =R9/$G9 -> 0.65529779 | M9: =S9/$G9 -> 0 | N9: =T9/$G9 -> 0.094704959 | O9: =U9/$G9 -> 0.057477483 | P9: =V9/$G9 -> 0.19251977 | Q9: =SUMIFS(InterventionCosts!$K$2:$K$3432,InterventionCosts!$D$2:$D$3432,'Summary of unit costs'!Q$1,InterventionCosts!$A$2:$A$3432,'Summary of unit costs'!$A9) -> 0 | R9: =SUMIFS(InterventionCosts!$K$2:$K$3432,InterventionCosts!$D$2:$D$3432,'Summary of unit costs'!R$1,InterventionCosts!$A$2:$A$3432,'Summary of unit costs'!$A9) -> 4024.824 | S9: =SUMIFS(InterventionCosts!$K$2:$K$3432,InterventionCosts!$D$2:$D$3432,'Summary of unit costs'!S$1,InterventionCosts!$A$2:$A$3432,'Summary of unit costs'!$A9) -> 0 | T9: =SUMIFS(InterventionCosts!$K$2:$K$3432,InterventionCosts!$D$2:$D$3432,'Summary of unit costs'!T$1,InterventionCosts!$A$2:$A$3432,'Summary of unit costs'!$A9) -> 581.67569 | U9: =SUMIFS(InterventionCosts!$K$2:$K$3432,InterventionCosts!$D$2:$D$3432,'Summary of unit costs'!U$1,InterventionCosts!$A$2:$A$3432,'Summary of unit costs'!$A9) -> 353.02539 | V9: =SUMIFS(InterventionCosts!$K$2:$K$3432,InterventionCosts!$D$2:$D$3432,'Summary of unit costs'!V$1,InterventionCosts!$A$2:$A$3432,'Summary of unit costs'!$A9) -> 1182.452
A10: ART Paeds Kids 3-5 (1st year) | C10: Peadiatric ART, starting ART at ages 3-5 yrs | D10: 710 | E10: Ingredients | F10: ART | G10: {=IF(E10="Literature",INDEX(LiteratureCost!$I$2:$I$10,MATCH('Summary of unit costs'!A10,LiteratureCost!$A$2:$A$10,0)),INDEX(InterventionCosts!$L$1:$L$2363,MATCH(A10,IF(InterventionCosts!$F$1:$F$2363="Cost per intervention",InterventionCosts!$A$1:$A$2363),0)))} -> 9186.2243 | H10: =G10/exrate -> 492.27762 | I10: {=IF(E10="Literature",INDEX(LiteratureCost!$G$2:$G$22,MATCH('Summary of unit costs'!A10,LiteratureCost!$A$2:$A$22,0)),INDEX(InterventionCosts!$L$1:$L$3432,MATCH(A10,IF(InterventionCosts!$F$1:$F$3432="Unit",InterventionCosts!$A$1:$A$3432),0)))} -> per person per year | J10: =G10/SUM(Q10:V10) -> 1 | K10: =Q10/$G10 -> 0 | L10: =R10/$G10 -> 0.56770749 | M10: =S10/$G10 -> 0 | N10: =T10/$G10 -> 0.11721475 | O10: =U10/$G10 -> 0.0724403 | P10: =V10/$G10 -> 0.24263746 | Q10: =SUMIFS(InterventionCosts!$K$2:$K$3432,InterventionCosts!$D$2:$D$3432,'Summary of unit costs'!Q$1,InterventionCosts!$A$2:$A$3432,'Summary of unit costs'!$A10) -> 0 | R10: =SUMIFS(InterventionCosts!$K$2:$K$3432,InterventionCosts!$D$2:$D$3432,'Summary of unit costs'!R$1,InterventionCosts!$A$2:$A$3432,'Summary of unit costs'!$A10) -> 5215.0884 | S10: =SUMIFS(InterventionCosts!$K$2:$K$3432,InterventionCosts!$D$2:$D$3432,'Summary of unit costs'!S$1,InterventionCosts!$A$2:$A$3432,'Summary of unit costs'!$A10) -> 0 | T10: =SUMIFS(InterventionCosts!$K$2:$K$3432,InterventionCosts!$D$2:$D$3432,'Summary of unit costs'!T$1,InterventionCosts!$A$2:$A$3432,'Summary of unit costs'!$A10) -> 1076.761 | U10: =SUMIFS(InterventionCosts!$K$2:$K$3432,InterventionCosts!$D$2:$D$3432,'Summary of unit costs'!U$1,InterventionCosts!$A$2:$A$3432,'Summary of unit costs'!$A10) -> 665.45285 | V10: =SUMIFS(InterventionCosts!$K$2:$K$3432,InterventionCosts!$D$2:$D$3432,'Summary of unit costs'!V$1,InterventionCosts!$A$2:$A$3432,'Summary of unit costs'!$A10) -> 2228.9221
A11: ART Paeds Kids 3-5 (followup) | C11: Peadiatric ART, in year after initiation at ages 3-5 yrs | D11: 5887 | E11: Ingredients | F11: ART | G11: {=IF(E11="Literature",INDEX(LiteratureCost!$I$2:$I$10,MATCH('Summary of unit costs'!A11,LiteratureCost!$A$2:$A$10,0)),INDEX(InterventionCosts!$L$1:$L$2363,MATCH(A11,IF(InterventionCosts!$F$1:$F$2363="Cost per intervention",InterventionCosts!$A$1:$A$2363),0)))} -> 7332.2415 | H11: =G11/exrate -> 392.92513 | I11: {=IF(E11="Literature",INDEX(LiteratureCost!$G$2:$G$22,MATCH('Summary of unit costs'!A11,LiteratureCost!$A$2:$A$22,0)),INDEX(InterventionCosts!$L$1:$L$3432,MATCH(A11,IF(InterventionCosts!$F$1:$F$3432="Unit",InterventionCosts!$A$1:$A$3432),0)))} -> per person per year | J11: =G11/SUM(Q11:V11) -> 1 | K11: =Q11/$G11 -> 0 | L11: =R11/$G11 -> 0.71125431 | M11: =S11/$G11 -> 0 | N11: =T11/$G11 -> 0.079331224 | O11: =U11/$G11 -> 0.048146994 | P11: =V11/$G11 -> 0.16126747 | Q11: =SUMIFS(InterventionCosts!$K$2:$K$3432,InterventionCosts!$D$2:$D$3432,'Summary of unit costs'!Q$1,InterventionCosts!$A$2:$A$3432,'Summary of unit costs'!$A11) -> 0 | R11: =SUMIFS(InterventionCosts!$K$2:$K$3432,InterventionCosts!$D$2:$D$3432,'Summary of unit costs'!R$1,InterventionCosts!$A$2:$A$3432,'Summary of unit costs'!$A11) -> 5215.0884 | S11: =SUMIFS(InterventionCosts!$K$2:$K$3432,InterventionCosts!$D$2:$D$3432,'Summary of unit costs'!S$1,InterventionCosts!$A$2:$A$3432,'Summary of unit costs'!$A11) -> 0 | T11: =SUMIFS(InterventionCosts!$K$2:$K$3432,InterventionCosts!$D$2:$D$3432,'Summary of unit costs'!T$1,InterventionCosts!$A$2:$A$3432,'Summary of unit costs'!$A11) -> 581.67569 | U11: =SUMIFS(InterventionCosts!$K$2:$K$3432,InterventionCosts!$D$2:$D$3432,'Summary of unit costs'!U$1,InterventionCosts!$A$2:$A$3432,'Summary of unit costs'!$A11) -> 353.02539 | V11: =SUMIFS(InterventionCosts!$K$2:$K$3432,InterventionCosts!$D$2:$D$3432,'Summary of unit costs'!V$1,InterventionCosts!$A$2:$A$3432,'Summary of unit costs'!$A11) -> 1182.452
A12: ART Paeds Kids 6-9 (1st year) | C12: Peadiatric ART, starting ART at ages 6-9 yrs | D12: 1121 | E12: Ingredients | F12: ART | G12: {=IF(E12="Literature",INDEX(LiteratureCost!$I$2:$I$10,MATCH('Summary of unit costs'!A12,LiteratureCost!$A$2:$A$10,0)),INDEX(InterventionCosts!$L$1:$L$2363,MATCH(A12,IF(InterventionCosts!$F$1:$F$2363="Cost per intervention",InterventionCosts!$A$1:$A$2363),0)))} -> 6812.4825 | H12: =G12/exrate -> 365.07194 | I12: {=IF(E12="Literature",INDEX(LiteratureCost!$G$2:$G$22,MATCH('Summary of unit costs'!A12,LiteratureCost!$A$2:$A$22,0)),INDEX(InterventionCosts!$L$1:$L$3432,MATCH(A12,IF(InterventionCosts!$F$1:$F$3432="Unit",InterventionCosts!$A$1:$A$3432),0)))} -> per person per year | J12: =G12/SUM(Q12:V12) -> 1 | K12: =Q12/$G12 -> 0 | L12: =R12/$G12 -> 0.41707946 | M12: =S12/$G12 -> 0 | N12: =T12/$G12 -> 0.15805707 | O12: =U12/$G12 -> 0.097681403 | P12: =V12/$G12 -> 0.32718206 | Q12: =SUMIFS(InterventionCosts!$K$2:$K$3432,InterventionCosts!$D$2:$D$3432,'Summary of unit costs'!Q$1,InterventionCosts!$A$2:$A$3432,'Summary of unit costs'!$A12) -> 0 | R12: =SUMIFS(InterventionCosts!$K$2:$K$3432,InterventionCosts!$D$2:$D$3432,'Summary of unit costs'!R$1,InterventionCosts!$A$2:$A$3432,'Summary of unit costs'!$A12) -> 2841.3466 | S12: =SUMIFS(InterventionCosts!$K$2:$K$3432,InterventionCosts!$D$2:$D$3432,'Summary of unit costs'!S$1,InterventionCosts!$A$2:$A$3432,'Summary of unit costs'!$A12) -> 0 | T12: =SUMIFS(InterventionCosts!$K$2:$K$3432,InterventionCosts!$D$2:$D$3432,'Summary of unit costs'!T$1,InterventionCosts!$A$2:$A$3432,'Summary of unit costs'!$A12) -> 1076.761 | U12: =SUMIFS(InterventionCosts!$K$2:$K$3432,InterventionCosts!$D$2:$D$3432,'Summary of unit costs'!U$1,InterventionCosts!$A$2:$A$3432,'Summary of unit costs'!$A12) -> 665.45285 | V12: =SUMIFS(InterventionCosts!$K$2:$K$3432,InterventionCosts!$D$2:$D$3432,'Summary of unit costs'!V$1,InterventionCosts!$A$2:$A$3432,'Summary of unit costs'!$A12) -> 2228.9221
A13: ART Paeds Kids 6-9 (followup) | C13: Peadiatric ART, in year after initiation at ages 6-9 yrs | D13: 14081 | E13: Ingredients | F13: ART | G13: {=IF(E13="Literature",INDEX(LiteratureCost!$I$2:$I$10,MATCH('Summary of unit costs'!A13,LiteratureCost!$A$2:$A$10,0)),INDEX(InterventionCosts!$L$1:$L$2363,MATCH(A13,IF(InterventionCosts!$F$1:$F$2363="Cost per intervention",InterventionCosts!$A$1:$A$2363),0)))} -> 4958.4997 | H13: =G13/exrate -> 265.71945 | I13: {=IF(E13="Literature",INDEX(LiteratureCost!$G$2:$G$22,MATCH('Summary of unit costs'!A13,LiteratureCost!$A$2:$A$22,0)),INDEX(InterventionCosts!$L$1:$L$3432,MATCH(A13,IF(InterventionCosts!$F$1:$F$3432="Unit",InterventionCosts!$A$1:$A$3432),0)))} -> per person per year | J13: =G13/SUM(Q13:V13) -> 1 | K13: =Q13/$G13 -> 0 | L13: =R13/$G13 -> 0.57302546 | M13: =S13/$G13 -> 0 | N13: =T13/$G13 -> 0.11730881 | O13: =U13/$G13 -> 0.071196008 | P13: =V13/$G13 -> 0.23846972 | Q13: =SUMIFS(InterventionCosts!$K$2:$K$3432,InterventionCosts!$D$2:$D$3432,'Summary of unit costs'!Q$1,InterventionCosts!$A$2:$A$3432,'Summary of unit costs'!$A13) -> 0 | R13: =SUMIFS(InterventionCosts!$K$2:$K$3432,InterventionCosts!$D$2:$D$3432,'Summary of unit costs'!R$1,InterventionCosts!$A$2:$A$3432,'Summary of unit costs'!$A13) -> 2841.3466 | S13: =SUMIFS(InterventionCosts!$K$2:$K$3432,InterventionCosts!$D$2:$D$3432,'Summary of unit costs'!S$1,InterventionCosts!$A$2:$A$3432,'Summary of unit costs'!$A13) -> 0 | T13: =SUMIFS(InterventionCosts!$K$2:$K$3432,InterventionCosts!$D$2:$D$3432,'Summary of unit costs'!T$1,InterventionCosts!$A$2:$A$3432,'Summary of unit costs'!$A13) -> 581.67569 | U13: =SUMIFS(InterventionCosts!$K$2:$K$3432,InterventionCosts!$D$2:$D$3432,'Summary of unit costs'!U$1,InterventionCosts!$A$2:$A$3432,'Summary of unit costs'!$A13) -> 353.02539 | V13: =SUMIFS(InterventionCosts!$K$2:$K$3432,InterventionCosts!$D$2:$D$3432,'Summary of unit costs'!V$1,InterventionCosts!$A$2:$A$3432,'Summary of unit costs'!$A13) -> 1182.452
A14: ART Paeds Kids 10-14 (1st year) | C14: Peadiatric ART, starting ART at ages 10-14 yrs | D14: 1196 | E14: Ingredients | F14: ART | G14: {=IF(E14="Literature",INDEX(LiteratureCost!$I$2:$I$10,MATCH('Summary of unit costs'!A14,LiteratureCost!$A$2:$A$10,0)),INDEX(InterventionCosts!$L$1:$L$2363,MATCH(A14,IF(InterventionCosts!$F$1:$F$2363="Cost per intervention",InterventionCosts!$A$1:$A$2363),0)))} -> 5584.7476 | H14: =G14/exrate -> 299.27924 | I14: {=IF(E14="Literature",INDEX(LiteratureCost!$G$2:$G$22,MATCH('Summary of unit costs'!A14,LiteratureCost!$A$2:$A$22,0)),INDEX(InterventionCosts!$L$1:$L$3432,MATCH(A14,IF(InterventionCosts!$F$1:$F$3432="Unit",InterventionCosts!$A$1:$A$3432),0)))} -> per person per year | J14: =G14/SUM(Q14:V14) -> 1 | K14: =Q14/$G14 -> 0 | L14: =R14/$G14 -> 0.28893188 | M14: =S14/$G14 -> 0 | N14: =T14/$G14 -> 0.19280388 | O14: =U14/$G14 -> 0.1191554 | P14: =V14/$G14 -> 0.39910884 | Q14: =SUMIFS(InterventionCosts!$K$2:$K$3432,InterventionCosts!$D$2:$D$3432,'Summary of unit costs'!Q$1,InterventionCosts!$A$2:$A$3432,'Summary of unit costs'!$A14) -> 0 | R14: =SUMIFS(InterventionCosts!$K$2:$K$3432,InterventionCosts!$D$2:$D$3432,'Summary of unit costs'!R$1,InterventionCosts!$A$2:$A$3432,'Summary of unit costs'!$A14) -> 1613.6116 | S14: =SUMIFS(InterventionCosts!$K$2:$K$3432,InterventionCosts!$D$2:$D$3432,'Summary of unit costs'!S$1,InterventionCosts!$A$2:$A$3432,'Summary of unit costs'!$A14) -> 0 | T14: =SUMIFS(InterventionCosts!$K$2:$K$3432,InterventionCosts!$D$2:$D$3432,'Summary of unit costs'!T$1,InterventionCosts!$A$2:$A$3432,'Summary of unit costs'!$A14) -> 1076.761 | U14: =SUMIFS(InterventionCosts!$K$2:$K$3432,InterventionCosts!$D$2:$D$3432,'Summary of unit costs'!U$1,InterventionCosts!$A$2:$A$3432,'Summary of unit costs'!$A14) -> 665.45285 | V14: =SUMIFS(InterventionCosts!$K$2:$K$3432,InterventionCosts!$D$2:$D$3432,'Summary of unit costs'!V$1,InterventionCosts!$A$2:$A$3432,'Summary of unit costs'!$A14) -> 2228.9221
A15: ART Paeds Kids 10-14 (followup) | C15: Peadiatric ART, in year after initiation at ages 10-14 yrs | D15: 40359 | E15: Ingredients | F15: ART | G15: {=IF(E15="Literature",INDEX(LiteratureCost!$I$2:$I$10,MATCH('Summary of unit costs'!A15,LiteratureCost!$A$2:$A$10,0)),INDEX(InterventionCosts!$L$1:$L$2363,MATCH(A15,IF(InterventionCosts!$F$1:$F$2363="Cost per intervention",InterventionCosts!$A$1:$A$2363),0)))} -> 3730.7647 | H15: =G15/exrate -> 199.92675 | I15: {=IF(E15="Literature",INDEX(LiteratureCost!$G$2:$G$22,MATCH('Summary of unit costs'!A15,LiteratureCost!$A$2:$A$22,0)),INDEX(InterventionCosts!$L$1:$L$3432,MATCH(A15,IF(InterventionCosts!$F$1:$F$3432="Unit",InterventionCosts!$A$1:$A$3432),0)))} -> per person per year | J15: =G15/SUM(Q15:V15) -> 1 | K15: =Q15/$G15 -> 0 | L15: =R15/$G15 -> 0.43251497 | M15: =S15/$G15 -> 0 | N15: =T15/$G15 -> 0.15591326 | O15: =U15/$G15 -> 0.094625476 | P15: =V15/$G15 -> 0.31694629 | Q15: =SUMIFS(InterventionCosts!$K$2:$K$3432,InterventionCosts!$D$2:$D$3432,'Summary of unit costs'!Q$1,InterventionCosts!$A$2:$A$3432,'Summary of unit costs'!$A15) -> 0 | R15: =SUMIFS(InterventionCosts!$K$2:$K$3432,InterventionCosts!$D$2:$D$3432,'Summary of unit costs'!R$1,InterventionCosts!$A$2:$A$3432,'Summary of unit costs'!$A15) -> 1613.6116 | S15: =SUMIFS(InterventionCosts!$K$2:$K$3432,InterventionCosts!$D$2:$D$3432,'Summary of unit costs'!S$1,InterventionCosts!$A$2:$A$3432,'Summary of unit costs'!$A15) -> 0 | T15: =SUMIFS(InterventionCosts!$K$2:$K$3432,InterventionCosts!$D$2:$D$3432,'Summary of unit costs'!T$1,InterventionCosts!$A$2:$A$3432,'Summary of unit costs'!$A15) -> 581.67569 | U15: =SUMIFS(InterventionCosts!$K$2:$K$3432,InterventionCosts!$D$2:$D$3432,'Summary of unit costs'!U$1,InterventionCosts!$A$2:$A$3432,'Summary of unit costs'!$A15) -> 353.02539 | V15: =SUMIFS(InterventionCosts!$K$2:$K$3432,InterventionCosts!$D$2:$D$3432,'Summary of unit costs'!V$1,InterventionCosts!$A$2:$A$3432,'Summary of unit costs'!$A15) -> 1182.452
A16: ART Paed (average cost) | C16: Average cost estimate of above, weighted by est. population size | E16: Ingredients | F16: ART | G16: =SUMPRODUCT(G7:G15,$D$7:$D$15)/SUM($D$7:$D$15) -> 4589.8057 | H16: =G16/exrate -> 245.96162 | I16: per person per year | J16: =G16/SUM(Q16:V16) -> 1 | K16: =Q16/$G16 -> 0 | L16: =R16/$G16 -> 0.51506967 | M16: =S16/$G16 -> 0 | N16: =T16/$G16 -> 0.13222422 | O16: =U16/$G16 -> 0.08109153 | P16: =V16/$G16 -> 0.27161459 | Q16: =SUMPRODUCT(Q7:Q15,$D$7:$D$15)/SUM($D$7:$D$15) -> 0 | R16: =SUMPRODUCT(R7:R15,$D$7:$D$15)/SUM($D$7:$D$15) -> 2364.0697 | S16: =SUMPRODUCT(S7:S15,$D$7:$D$15)/SUM($D$7:$D$15) -> 0 | T16: =SUMPRODUCT(T7:T15,$D$7:$D$15)/SUM($D$7:$D$15) -> 606.88346 | U16: =SUMPRODUCT(U7:U15,$D$7:$D$15)/SUM($D$7:$D$15) -> 372.19437 | V16: =SUMPRODUCT(V7:V15,$D$7:$D$15)/SUM($D$7:$D$15) -> 1246.6582
A17: POC VL testing | C17: Adults on ART in 20% of clinics (high demand clinics) | E17: Ingredients | F17: ART | G17: {=IF(E17="Literature",INDEX(LiteratureCost!$I$2:$I$42,MATCH('Summary of unit costs'!A17,LiteratureCost!$A$2:$A$42,0)),INDEX(InterventionCosts!$L$1:$L$3432,MATCH(A17,IF(InterventionCosts!$F$1:$F$3432="Cost per intervention",InterventionCosts!$A$1:$A$3432),0)))} -> 564.88179 | H17: =G17/exrate -> 30.271269 | I17: {=IF(E17="Literature",INDEX(LiteratureCost!$G$2:$G$22,MATCH('Summary of unit costs'!A17,LiteratureCost!$A$2:$A$22,0)),INDEX(InterventionCosts!$L$1:$L$3432,MATCH(A17,IF(InterventionCosts!$F$1:$F$3432="Unit",InterventionCosts!$A$1:$A$3432),0)))} -> per test | K17: =Q17/$G17 -> 0.57243639 | L17: =R17/$G17 -> 0 | M17: =S17/$G17 -> 0.13921977 | N17: =T17/$G17 -> 0 | O17: =U17/$G17 -> 0.084028752 | P17: =V17/$G17 -> 0.20431509 | Q17: =SUMIFS(InterventionCosts!$K$2:$K$3432,InterventionCosts!$D$2:$D$3432,'Summary of unit costs'!Q$1,InterventionCosts!$A$2:$A$3432,'Summary of unit costs'!$A17) -> 323.35889 | R17: =SUMIFS(InterventionCosts!$K$2:$K$3432,InterventionCosts!$D$2:$D$3432,'Summary of unit costs'!R$1,InterventionCosts!$A$2:$A$3432,'Summary of unit costs'!$A17) -> 0 | S17: =SUMIFS(InterventionCosts!$K$2:$K$3432,InterventionCosts!$D$2:$D$3432,'Summary of unit costs'!S$1,InterventionCosts!$A$2:$A$3432,'Summary of unit costs'!$A17) -> 78.64271 | T17: =SUMIFS(InterventionCosts!$K$2:$K$3432,InterventionCosts!$D$2:$D$3432,'Summary of unit costs'!T$1,InterventionCosts!$A$2:$A$3432,'Summary of unit costs'!$A17) -> 0 | U17: =SUMIFS(InterventionCosts!$K$2:$K$3432,InterventionCosts!$D$2:$D$3432,'Summary of unit costs'!U$1,InterventionCosts!$A$2:$A$3432,'Summary of unit costs'!$A17) -> 47.466312 | V17: =SUMIFS(InterventionCosts!$K$2:$K$3432,InterventionCosts!$D$2:$D$3432,'Summary of unit costs'!V$1,InterventionCosts!$A$2:$A$3432,'Summary of unit costs'!$A17) -> 115.41387
A18: ART with POCVL Adults (1st line 1st year) | C18: As ART costs above, but replacing PCR-based VL with point-of-care GeneXpert testing | E18: Ingredients | F18: ART | G18: {=IF(E18="Literature",INDEX(LiteratureCost!$I$2:$I$10,MATCH('Summary of unit costs'!A18,LiteratureCost!$A$2:$A$10,0)),INDEX(InterventionCosts!$L$1:$L$2363,MATCH(A18,IF(InterventionCosts!$F$1:$F$2363="Cost per intervention",InterventionCosts!$A$1:$A$2363),0)))} -> 5484.0979 | H18: =G18/exrate -> 293.88556 | I18: per person per year | J18: =G18/SUM(Q18:V18) -> 1 | K18: =Q18/$G18 -> 0.11792601 | L18: =R18/$G18 -> 0.23748844 | M18: =S18/$G18 -> 0.028680272 | N18: =T18/$G18 -> 0.030209038 | O18: =U18/$G18 -> 0.13865279 | P18: =V18/$G18 -> 0.44704345 | Q18: =SUMIFS(InterventionCosts!$K$2:$K$3432,InterventionCosts!$D$2:$D$3432,'Summary of unit costs'!Q$1,InterventionCosts!$A$2:$A$3432,'Summary of unit costs'!$A18) -> 646.71779 | R18: =SUMIFS(InterventionCosts!$K$2:$K$3432,InterventionCosts!$D$2:$D$3432,'Summary of unit costs'!R$1,InterventionCosts!$A$2:$A$3432,'Summary of unit costs'!$A18) -> 1302.4098 | S18: =SUMIFS(InterventionCosts!$K$2:$K$3432,InterventionCosts!$D$2:$D$3432,'Summary of unit costs'!S$1,InterventionCosts!$A$2:$A$3432,'Summary of unit costs'!$A18) -> 157.28542 | T18: =SUMIFS(InterventionCosts!$K$2:$K$3432,InterventionCosts!$D$2:$D$3432,'Summary of unit costs'!T$1,InterventionCosts!$A$2:$A$3432,'Summary of unit costs'!$A18) -> 165.66932 | U18: =SUMIFS(InterventionCosts!$K$2:$K$3432,InterventionCosts!$D$2:$D$3432,'Summary of unit costs'!U$1,InterventionCosts!$A$2:$A$3432,'Summary of unit costs'!$A18) -> 760.38547 | V18: =SUMIFS(InterventionCosts!$K$2:$K$3432,InterventionCosts!$D$2:$D$3432,'Summary of unit costs'!V$1,InterventionCosts!$A$2:$A$3432,'Summary of unit costs'!$A18) -> 2451.63
A19: ART with POCVL Adults (1st line followup) | C19: As ART costs above, but replacing PCR-based VL with point-of-care GeneXpert testing | E19: Ingredients | F19: ART | G19: {=IF(E19="Literature",INDEX(LiteratureCost!$I$2:$I$10,MATCH('Summary of unit costs'!A19,LiteratureCost!$A$2:$A$10,0)),INDEX(InterventionCosts!$L$1:$L$2363,MATCH(A19,IF(InterventionCosts!$F$1:$F$2363="Cost per intervention",InterventionCosts!$A$1:$A$2363),0)))} -> 3416.3737 | H19: =G19/exrate -> 183.07895 | I19: per person per year | J19: =G19/SUM(Q19:V19) -> 1 | K19: =Q19/$G19 -> 0.094649742 | L19: =R19/$G19 -> 0.34828879 | M19: =S19/$G19 -> 0.023019352 | N19: =T19/$G19 -> 0.036919218 | O19: =U19/$G19 -> 0.11722713 | P19: =V19/$G19 -> 0.37989576 | Q19: =SUMIFS(InterventionCosts!$K$2:$K$3432,InterventionCosts!$D$2:$D$3432,'Summary of unit costs'!Q$1,InterventionCosts!$A$2:$A$3432,'Summary of unit costs'!$A19) -> 323.35889 | R19: =SUMIFS(InterventionCosts!$K$2:$K$3432,InterventionCosts!$D$2:$D$3432,'Summary of unit costs'!R$1,InterventionCosts!$A$2:$A$3432,'Summary of unit costs'!$A19) -> 1189.8847 | S19: =SUMIFS(InterventionCosts!$K$2:$K$3432,InterventionCosts!$D$2:$D$3432,'Summary of unit costs'!S$1,InterventionCosts!$A$2:$A$3432,'Summary of unit costs'!$A19) -> 78.64271 | T19: =SUMIFS(InterventionCosts!$K$2:$K$3432,InterventionCosts!$D$2:$D$3432,'Summary of unit costs'!T$1,InterventionCosts!$A$2:$A$3432,'Summary of unit costs'!$A19) -> 126.12985 | U19: =SUMIFS(InterventionCosts!$K$2:$K$3432,InterventionCosts!$D$2:$D$3432,'Summary of unit costs'!U$1,InterventionCosts!$A$2:$A$3432,'Summary of unit costs'!$A19) -> 400.4917 | V19: =SUMIFS(InterventionCosts!$K$2:$K$3432,InterventionCosts!$D$2:$D$3432,'Summary of unit costs'!V$1,InterventionCosts!$A$2:$A$3432,'Summary of unit costs'!$A19) -> 1297.8659
A20: ART with POCVL Adults (2nd line followup) | C20: As ART costs above, but replacing PCR-based VL with point-of-care GeneXpert testing | E20: Ingredients | F20: ART | G20: {=IF(E20="Literature",INDEX(LiteratureCost!$I$2:$I$10,MATCH('Summary of unit costs'!A20,LiteratureCost!$A$2:$A$10,0)),INDEX(InterventionCosts!$L$1:$L$2363,MATCH(A20,IF(InterventionCosts!$F$1:$F$2363="Cost per intervention",InterventionCosts!$A$1:$A$2363),0)))} -> 6022.1141 | H20: =G20/exrate -> 322.71713 | I20: per person per year | J20: =G20/SUM(Q20:V20) -> 1 | K20: =Q20/$G20 -> 0.10739049 | L20: =R20/$G20 -> 0.47273662 | M20: =S20/$G20 -> 0.026117974 | N20: =T20/$G20 -> 0.020944446 | O20: =U20/$G20 -> 0.089040883 | P20: =V20/$G20 -> 0.28376958 | Q20: =SUMIFS(InterventionCosts!$K$2:$K$3432,InterventionCosts!$D$2:$D$3432,'Summary of unit costs'!Q$1,InterventionCosts!$A$2:$A$3432,'Summary of unit costs'!$A20) -> 646.71779 | R20: =SUMIFS(InterventionCosts!$K$2:$K$3432,InterventionCosts!$D$2:$D$3432,'Summary of unit costs'!R$1,InterventionCosts!$A$2:$A$3432,'Summary of unit costs'!$A20) -> 2846.8739 | S20: =SUMIFS(InterventionCosts!$K$2:$K$3432,InterventionCosts!$D$2:$D$3432,'Summary of unit costs'!S$1,InterventionCosts!$A$2:$A$3432,'Summary of unit costs'!$A20) -> 157.28542 | T20: =SUMIFS(InterventionCosts!$K$2:$K$3432,InterventionCosts!$D$2:$D$3432,'Summary of unit costs'!T$1,InterventionCosts!$A$2:$A$3432,'Summary of unit costs'!$A20) -> 126.12985 | U20: =SUMIFS(InterventionCosts!$K$2:$K$3432,InterventionCosts!$D$2:$D$3432,'Summary of unit costs'!U$1,InterventionCosts!$A$2:$A$3432,'Summary of unit costs'!$A20) -> 536.21435 | V20: =SUMIFS(InterventionCosts!$K$2:$K$3432,InterventionCosts!$D$2:$D$3432,'Summary of unit costs'!V$1,InterventionCosts!$A$2:$A$3432,'Summary of unit costs'!$A20) -> 1708.8928
A21: ART with POCVL Paeds Kids <1 | C21: As ART costs above, but replacing PCR-based VL with point-of-care GeneXpert testing | E21: Ingredients | F21: ART | G21: {=IF(E21="Literature",INDEX(LiteratureCost!$I$2:$I$10,MATCH('Summary of unit costs'!A21,LiteratureCost!$A$2:$A$10,0)),INDEX(InterventionCosts!$L$1:$L$2363,MATCH(A21,IF(InterventionCosts!$F$1:$F$2363="Cost per intervention",InterventionCosts!$A$1:$A$2363),0)))} -> 5654.1133 | H21: =G21/exrate -> 302.99646 | I21: per person per year | J21: =G21/SUM(Q21:V21) -> 1 | K21: =Q21/$G21 -> 0.057190027 | L21: =R21/$G21 -> 0.372873 | M21: =S21/$G21 -> 0.013908938 | N21: =T21/$G21 -> 0.01531458 | O21: =U21/$G21 -> 0.12608859 | P21: =V21/$G21 -> 0.41462487 | Q21: =SUMIFS(InterventionCosts!$K$2:$K$3432,InterventionCosts!$D$2:$D$3432,'Summary of unit costs'!Q$1,InterventionCosts!$A$2:$A$3432,'Summary of unit costs'!$A21) -> 323.35889 | R21: =SUMIFS(InterventionCosts!$K$2:$K$3432,InterventionCosts!$D$2:$D$3432,'Summary of unit costs'!R$1,InterventionCosts!$A$2:$A$3432,'Summary of unit costs'!$A21) -> 2108.2662 | S21: =SUMIFS(InterventionCosts!$K$2:$K$3432,InterventionCosts!$D$2:$D$3432,'Summary of unit costs'!S$1,InterventionCosts!$A$2:$A$3432,'Summary of unit costs'!$A21) -> 78.64271 | T21: =SUMIFS(InterventionCosts!$K$2:$K$3432,InterventionCosts!$D$2:$D$3432,'Summary of unit costs'!T$1,InterventionCosts!$A$2:$A$3432,'Summary of unit costs'!$A21) -> 86.590372 | U21: =SUMIFS(InterventionCosts!$K$2:$K$3432,InterventionCosts!$D$2:$D$3432,'Summary of unit costs'!U$1,InterventionCosts!$A$2:$A$3432,'Summary of unit costs'!$A21) -> 712.91916 | V21: =SUMIFS(InterventionCosts!$K$2:$K$3432,InterventionCosts!$D$2:$D$3432,'Summary of unit costs'!V$1,InterventionCosts!$A$2:$A$3432,'Summary of unit costs'!$A21) -> 2344.336
A22: ART with POCVL Paeds Kids 1-2 (1st year) | C22: As ART costs above, but replacing PCR-based VL with point-of-care GeneXpert testing | E22: Ingredients | F22: ART | G22: {=IF(E22="Literature",INDEX(LiteratureCost!$I$2:$I$10,MATCH('Summary of unit costs'!A22,LiteratureCost!$A$2:$A$10,0)),INDEX(InterventionCosts!$L$1:$L$2363,MATCH(A22,IF(InterventionCosts!$F$1:$F$2363="Cost per intervention",InterventionCosts!$A$1:$A$2363),0)))} -> 8135.5529 | H22: =G22/exrate -> 435.97353 | I22: per person per year | J22: =G22/SUM(Q22:V22) -> 1 | K22: =Q22/$G22 -> 0.079492788 | L22: =R22/$G22 -> 0.4947204 | M22: =S22/$G22 -> 0.019333095 | N22: =T22/$G22 -> 0.010643453 | O22: =U22/$G22 -> 0.093464511 | P22: =V22/$G22 -> 0.30234575 | Q22: =SUMIFS(InterventionCosts!$K$2:$K$3432,InterventionCosts!$D$2:$D$3432,'Summary of unit costs'!Q$1,InterventionCosts!$A$2:$A$3432,'Summary of unit costs'!$A22) -> 646.71779 | R22: =SUMIFS(InterventionCosts!$K$2:$K$3432,InterventionCosts!$D$2:$D$3432,'Summary of unit costs'!R$1,InterventionCosts!$A$2:$A$3432,'Summary of unit costs'!$A22) -> 4024.824 | S22: =SUMIFS(InterventionCosts!$K$2:$K$3432,InterventionCosts!$D$2:$D$3432,'Summary of unit costs'!S$1,InterventionCosts!$A$2:$A$3432,'Summary of unit costs'!$A22) -> 157.28542 | T22: =SUMIFS(InterventionCosts!$K$2:$K$3432,InterventionCosts!$D$2:$D$3432,'Summary of unit costs'!T$1,InterventionCosts!$A$2:$A$3432,'Summary of unit costs'!$A22) -> 86.590372 | U22: =SUMIFS(InterventionCosts!$K$2:$K$3432,InterventionCosts!$D$2:$D$3432,'Summary of unit costs'!U$1,InterventionCosts!$A$2:$A$3432,'Summary of unit costs'!$A22) -> 760.38547 | V22: =SUMIFS(InterventionCosts!$K$2:$K$3432,InterventionCosts!$D$2:$D$3432,'Summary of unit costs'!V$1,InterventionCosts!$A$2:$A$3432,'Summary of unit costs'!$A22) -> 2459.7498
A23: ART with POCVL Paeds Kids 1-2 (followup) | C23: As ART costs above, but replacing PCR-based VL with point-of-care GeneXpert testing | E23: Ingredients | F23: ART | G23: {=IF(E23="Literature",INDEX(LiteratureCost!$I$2:$I$10,MATCH('Summary of unit costs'!A23,LiteratureCost!$A$2:$A$10,0)),INDEX(InterventionCosts!$L$1:$L$2363,MATCH(A23,IF(InterventionCosts!$F$1:$F$2363="Cost per intervention",InterventionCosts!$A$1:$A$2363),0)))} -> 6211.7736 | H23: =G23/exrate -> 332.88074 | I23: per person per year | J23: =G23/SUM(Q23:V23) -> 1 | K23: =Q23/$G23 -> 0.052055808 | L23: =R23/$G23 -> 0.64793476 | M23: =S23/$G23 -> 0.012660267 | N23: =T23/$G23 -> 0.013939718 | O23: =U23/$G23 -> 0.064473003 | P23: =V23/$G23 -> 0.20893645 | Q23: =SUMIFS(InterventionCosts!$K$2:$K$3432,InterventionCosts!$D$2:$D$3432,'Summary of unit costs'!Q$1,InterventionCosts!$A$2:$A$3432,'Summary of unit costs'!$A23) -> 323.35889 | R23: =SUMIFS(InterventionCosts!$K$2:$K$3432,InterventionCosts!$D$2:$D$3432,'Summary of unit costs'!R$1,InterventionCosts!$A$2:$A$3432,'Summary of unit costs'!$A23) -> 4024.824 | S23: =SUMIFS(InterventionCosts!$K$2:$K$3432,InterventionCosts!$D$2:$D$3432,'Summary of unit costs'!S$1,InterventionCosts!$A$2:$A$3432,'Summary of unit costs'!$A23) -> 78.64271 | T23: =SUMIFS(InterventionCosts!$K$2:$K$3432,InterventionCosts!$D$2:$D$3432,'Summary of unit costs'!T$1,InterventionCosts!$A$2:$A$3432,'Summary of unit costs'!$A23) -> 86.590372 | U23: =SUMIFS(InterventionCosts!$K$2:$K$3432,InterventionCosts!$D$2:$D$3432,'Summary of unit costs'!U$1,InterventionCosts!$A$2:$A$3432,'Summary of unit costs'!$A23) -> 400.4917 | V23: =SUMIFS(InterventionCosts!$K$2:$K$3432,InterventionCosts!$D$2:$D$3432,'Summary of unit costs'!V$1,InterventionCosts!$A$2:$A$3432,'Summary of unit costs'!$A23) -> 1297.8659
A24: ART with POCVL Paeds Kids 3-5 (1st year) | C24: As ART costs above, but replacing PCR-based VL with point-of-care GeneXpert testing | E24: Ingredients | F24: ART | G24: {=IF(E24="Literature",INDEX(LiteratureCost!$I$2:$I$10,MATCH('Summary of unit costs'!A24,LiteratureCost!$A$2:$A$10,0)),INDEX(InterventionCosts!$L$1:$L$2363,MATCH(A24,IF(InterventionCosts!$F$1:$F$2363="Cost per intervention",InterventionCosts!$A$1:$A$2363),0)))} -> 9325.8173 | H24: =G24/exrate -> 499.75822 | I24: per person per year | J24: =G24/SUM(Q24:V24) -> 1 | K24: =Q24/$G24 -> 0.069347036 | L24: =R24/$G24 -> 0.5592098 | M24: =S24/$G24 -> 0.016865591 | N24: =T24/$G24 -> 0.009285017 | O24: =U24/$G24 -> 0.081535532 | P24: =V24/$G24 -> 0.26375703 | Q24: =SUMIFS(InterventionCosts!$K$2:$K$3432,InterventionCosts!$D$2:$D$3432,'Summary of unit costs'!Q$1,InterventionCosts!$A$2:$A$3432,'Summary of unit costs'!$A24) -> 646.71779 | R24: =SUMIFS(InterventionCosts!$K$2:$K$3432,InterventionCosts!$D$2:$D$3432,'Summary of unit costs'!R$1,InterventionCosts!$A$2:$A$3432,'Summary of unit costs'!$A24) -> 5215.0884 | S24: =SUMIFS(InterventionCosts!$K$2:$K$3432,InterventionCosts!$D$2:$D$3432,'Summary of unit costs'!S$1,InterventionCosts!$A$2:$A$3432,'Summary of unit costs'!$A24) -> 157.28542 | T24: =SUMIFS(InterventionCosts!$K$2:$K$3432,InterventionCosts!$D$2:$D$3432,'Summary of unit costs'!T$1,InterventionCosts!$A$2:$A$3432,'Summary of unit costs'!$A24) -> 86.590372 | U24: =SUMIFS(InterventionCosts!$K$2:$K$3432,InterventionCosts!$D$2:$D$3432,'Summary of unit costs'!U$1,InterventionCosts!$A$2:$A$3432,'Summary of unit costs'!$A24) -> 760.38547 | V24: =SUMIFS(InterventionCosts!$K$2:$K$3432,InterventionCosts!$D$2:$D$3432,'Summary of unit costs'!V$1,InterventionCosts!$A$2:$A$3432,'Summary of unit costs'!$A24) -> 2459.7498
A25: ART with POCVL Paeds Kids 3-5 (followup) | C25: As ART costs above, but replacing PCR-based VL with point-of-care GeneXpert testing | E25: Ingredients | F25: ART | G25: {=IF(E25="Literature",INDEX(LiteratureCost!$I$2:$I$10,MATCH('Summary of unit costs'!A25,LiteratureCost!$A$2:$A$10,0)),INDEX(InterventionCosts!$L$1:$L$2363,MATCH(A25,IF(InterventionCosts!$F$1:$F$2363="Cost per intervention",InterventionCosts!$A$1:$A$2363),0)))} -> 7402.038 | H25: =G25/exrate -> 396.66543 | I25: per person per year | J25: =G25/SUM(Q25:V25) -> 1 | K25: =Q25/$G25 -> 0.043685117 | L25: =R25/$G25 -> 0.70454764 | M25: =S25/$G25 -> 0.010624467 | N25: =T25/$G25 -> 0.01169818 | O25: =U25/$G25 -> 0.054105599 | P25: =V25/$G25 -> 0.175339 | Q25: =SUMIFS(InterventionCosts!$K$2:$K$3432,InterventionCosts!$D$2:$D$3432,'Summary of unit costs'!Q$1,InterventionCosts!$A$2:$A$3432,'Summary of unit costs'!$A25) -> 323.35889 | R25: =SUMIFS(InterventionCosts!$K$2:$K$3432,InterventionCosts!$D$2:$D$3432,'Summary of unit costs'!R$1,InterventionCosts!$A$2:$A$3432,'Summary of unit costs'!$A25) -> 5215.0884 | S25: =SUMIFS(InterventionCosts!$K$2:$K$3432,InterventionCosts!$D$2:$D$3432,'Summary of unit costs'!S$1,InterventionCosts!$A$2:$A$3432,'Summary of unit costs'!$A25) -> 78.64271 | T25: =SUMIFS(InterventionCosts!$K$2:$K$3432,InterventionCosts!$D$2:$D$3432,'Summary of unit costs'!T$1,InterventionCosts!$A$2:$A$3432,'Summary of unit costs'!$A25) -> 86.590372 | U25: =SUMIFS(InterventionCosts!$K$2:$K$3432,InterventionCosts!$D$2:$D$3432,'Summary of unit costs'!U$1,InterventionCosts!$A$2:$A$3432,'Summary of unit costs'!$A25) -> 400.4917 | V25: =SUMIFS(InterventionCosts!$K$2:$K$3432,InterventionCosts!$D$2:$D$3432,'Summary of unit costs'!V$1,InterventionCosts!$A$2:$A$3432,'Summary of unit costs'!$A25) -> 1297.8659
A26: ART with POCVL Paeds Kids 6-9 (1st year) | C26: As ART costs above, but replacing PCR-based VL with point-of-care GeneXpert testing | E26: Ingredients | F26: ART | G26: {=IF(E26="Literature",INDEX(LiteratureCost!$I$2:$I$10,MATCH('Summary of unit costs'!A26,LiteratureCost!$A$2:$A$10,0)),INDEX(InterventionCosts!$L$1:$L$2363,MATCH(A26,IF(InterventionCosts!$F$1:$F$2363="Cost per intervention",InterventionCosts!$A$1:$A$2363),0)))} -> 6952.0755 | H26: =G26/exrate -> 372.55254 | I26: per person per year | J26: =G26/SUM(Q26:V26) -> 1 | K26: =Q26/$G26 -> 0.093025139 | L26: =R26/$G26 -> 0.40870479 | M26: =S26/$G26 -> 0.022624239 | N26: =T26/$G26 -> 0.012455327 | O26: =U26/$G26 -> 0.10937532 | P26: =V26/$G26 -> 0.35381518 | Q26: =SUMIFS(InterventionCosts!$K$2:$K$3432,InterventionCosts!$D$2:$D$3432,'Summary of unit costs'!Q$1,InterventionCosts!$A$2:$A$3432,'Summary of unit costs'!$A26) -> 646.71779 | R26: =SUMIFS(InterventionCosts!$K$2:$K$3432,InterventionCosts!$D$2:$D$3432,'Summary of unit costs'!R$1,InterventionCosts!$A$2:$A$3432,'Summary of unit costs'!$A26) -> 2841.3466 | S26: =SUMIFS(InterventionCosts!$K$2:$K$3432,InterventionCosts!$D$2:$D$3432,'Summary of unit costs'!S$1,InterventionCosts!$A$2:$A$3432,'Summary of unit costs'!$A26) -> 157.28542 | T26: =SUMIFS(InterventionCosts!$K$2:$K$3432,InterventionCosts!$D$2:$D$3432,'Summary of unit costs'!T$1,InterventionCosts!$A$2:$A$3432,'Summary of unit costs'!$A26) -> 86.590372 | U26: =SUMIFS(InterventionCosts!$K$2:$K$3432,InterventionCosts!$D$2:$D$3432,'Summary of unit costs'!U$1,InterventionCosts!$A$2:$A$3432,'Summary of unit costs'!$A26) -> 760.38547 | V26: =SUMIFS(InterventionCosts!$K$2:$K$3432,InterventionCosts!$D$2:$D$3432,'Summary of unit costs'!V$1,InterventionCosts!$A$2:$A$3432,'Summary of unit costs'!$A26) -> 2459.7498
A27: ART with POCVL Paeds Kids 6-9 (followup) | C27: As ART costs above, but replacing PCR-based VL with point-of-care GeneXpert testing | E27: Ingredients | F27: ART | G27: {=IF(E27="Literature",INDEX(LiteratureCost!$I$2:$I$10,MATCH('Summary of unit costs'!A27,LiteratureCost!$A$2:$A$10,0)),INDEX(InterventionCosts!$L$1:$L$2363,MATCH(A27,IF(InterventionCosts!$F$1:$F$2363="Cost per intervention",InterventionCosts!$A$1:$A$2363),0)))} -> 5028.2962 | H27: =G27/exrate -> 269.45975 | I27: per person per year | J27: =G27/SUM(Q27:V27) -> 1 | K27: =Q27/$G27 -> 0.064307846 | L27: =R27/$G27 -> 0.56507144 | M27: =S27/$G27 -> 0.015640031 | N27: =T27/$G27 -> 0.017220619 | O27: =U27/$G27 -> 0.079647595 | P27: =V27/$G27 -> 0.25811247 | Q27: =SUMIFS(InterventionCosts!$K$2:$K$3432,InterventionCosts!$D$2:$D$3432,'Summary of unit costs'!Q$1,InterventionCosts!$A$2:$A$3432,'Summary of unit costs'!$A27) -> 323.35889 | R27: =SUMIFS(InterventionCosts!$K$2:$K$3432,InterventionCosts!$D$2:$D$3432,'Summary of unit costs'!R$1,InterventionCosts!$A$2:$A$3432,'Summary of unit costs'!$A27) -> 2841.3466 | S27: =SUMIFS(InterventionCosts!$K$2:$K$3432,InterventionCosts!$D$2:$D$3432,'Summary of unit costs'!S$1,InterventionCosts!$A$2:$A$3432,'Summary of unit costs'!$A27) -> 78.64271 | T27: =SUMIFS(InterventionCosts!$K$2:$K$3432,InterventionCosts!$D$2:$D$3432,'Summary of unit costs'!T$1,InterventionCosts!$A$2:$A$3432,'Summary of unit costs'!$A27) -> 86.590372 | U27: =SUMIFS(InterventionCosts!$K$2:$K$3432,InterventionCosts!$D$2:$D$3432,'Summary of unit costs'!U$1,InterventionCosts!$A$2:$A$3432,'Summary of unit costs'!$A27) -> 400.4917 | V27: =SUMIFS(InterventionCosts!$K$2:$K$3432,InterventionCosts!$D$2:$D$3432,'Summary of unit costs'!V$1,InterventionCosts!$A$2:$A$3432,'Summary of unit costs'!$A27) -> 1297.8659
A28: ART with POCVL Paeds Kids 10-14 (1st year) | C28: As ART costs above, but replacing PCR-based VL with point-of-care GeneXpert testing | E28: Ingredients | F28: ART | G28: {=IF(E28="Literature",INDEX(LiteratureCost!$I$2:$I$10,MATCH('Summary of unit costs'!A28,LiteratureCost!$A$2:$A$10,0)),INDEX(InterventionCosts!$L$1:$L$2363,MATCH(A28,IF(InterventionCosts!$F$1:$F$2363="Cost per intervention",InterventionCosts!$A$1:$A$2363),0)))} -> 5724.3405 | H28: =G28/exrate -> 306.75984 | I28: per person per year | J28: =G28/SUM(Q28:V28) -> 1 | K28: =Q28/$G28 -> 0.11297682 | L28: =R28/$G28 -> 0.28188603 | M28: =S28/$G28 -> 0.027476601 | N28: =T28/$G28 -> 0.015126698 | O28: =U28/$G28 -> 0.13283373 | P28: =V28/$G28 -> 0.42970013 | Q28: =SUMIFS(InterventionCosts!$K$2:$K$3432,InterventionCosts!$D$2:$D$3432,'Summary of unit costs'!Q$1,InterventionCosts!$A$2:$A$3432,'Summary of unit costs'!$A28) -> 646.71779 | R28: =SUMIFS(InterventionCosts!$K$2:$K$3432,InterventionCosts!$D$2:$D$3432,'Summary of unit costs'!R$1,InterventionCosts!$A$2:$A$3432,'Summary of unit costs'!$A28) -> 1613.6116 | S28: =SUMIFS(InterventionCosts!$K$2:$K$3432,InterventionCosts!$D$2:$D$3432,'Summary of unit costs'!S$1,InterventionCosts!$A$2:$A$3432,'Summary of unit costs'!$A28) -> 157.28542 | T28: =SUMIFS(InterventionCosts!$K$2:$K$3432,InterventionCosts!$D$2:$D$3432,'Summary of unit costs'!T$1,InterventionCosts!$A$2:$A$3432,'Summary of unit costs'!$A28) -> 86.590372 | U28: =SUMIFS(InterventionCosts!$K$2:$K$3432,InterventionCosts!$D$2:$D$3432,'Summary of unit costs'!U$1,InterventionCosts!$A$2:$A$3432,'Summary of unit costs'!$A28) -> 760.38547 | V28: =SUMIFS(InterventionCosts!$K$2:$K$3432,InterventionCosts!$D$2:$D$3432,'Summary of unit costs'!V$1,InterventionCosts!$A$2:$A$3432,'Summary of unit costs'!$A28) -> 2459.7498
A29: ART with POCVL Paeds Kids 10-14 (followup) | C29: As ART costs above, but replacing PCR-based VL with point-of-care GeneXpert testing | E29: Ingredients | F29: ART | G29: {=IF(E29="Literature",INDEX(LiteratureCost!$I$2:$I$10,MATCH('Summary of unit costs'!A29,LiteratureCost!$A$2:$A$10,0)),INDEX(InterventionCosts!$L$1:$L$2363,MATCH(A29,IF(InterventionCosts!$F$1:$F$2363="Cost per intervention",InterventionCosts!$A$1:$A$2363),0)))} -> 3800.5612 | H29: =G29/exrate -> 203.66705 | I29: per person per year | J29: =G29/SUM(Q29:V29) -> 1 | K29: =Q29/$G29 -> 0.085081881 | L29: =R29/$G29 -> 0.42457193 | M29: =S29/$G29 -> 0.020692394 | N29: =T29/$G29 -> 0.022783575 | O29: =U29/$G29 -> 0.10537699 | P29: =V29/$G29 -> 0.34149323 | Q29: =SUMIFS(InterventionCosts!$K$2:$K$3432,InterventionCosts!$D$2:$D$3432,'Summary of unit costs'!Q$1,InterventionCosts!$A$2:$A$3432,'Summary of unit costs'!$A29) -> 323.35889 | R29: =SUMIFS(InterventionCosts!$K$2:$K$3432,InterventionCosts!$D$2:$D$3432,'Summary of unit costs'!R$1,InterventionCosts!$A$2:$A$3432,'Summary of unit costs'!$A29) -> 1613.6116 | S29: =SUMIFS(InterventionCosts!$K$2:$K$3432,InterventionCosts!$D$2:$D$3432,'Summary of unit costs'!S$1,InterventionCosts!$A$2:$A$3432,'Summary of unit costs'!$A29) -> 78.64271 | T29: =SUMIFS(InterventionCosts!$K$2:$K$3432,InterventionCosts!$D$2:$D$3432,'Summary of unit costs'!T$1,InterventionCosts!$A$2:$A$3432,'Summary of unit costs'!$A29) -> 86.590372 | U29: =SUMIFS(InterventionCosts!$K$2:$K$3432,InterventionCosts!$D$2:$D$3432,'Summary of unit costs'!U$1,InterventionCosts!$A$2:$A$3432,'Summary of unit costs'!$A29) -> 400.4917 | V29: =SUMIFS(InterventionCosts!$K$2:$K$3432,InterventionCosts!$D$2:$D$3432,'Summary of unit costs'!V$1,InterventionCosts!$A$2:$A$3432,'Summary of unit costs'!$A29) -> 1297.8659
A30: Medical male circumcision | C30: Number of MMCs in 10+ year olds | E30: Ingredients | F30: MMC | G30: {=IF(E30="Literature",INDEX(LiteratureCost!$I$2:$I$10,MATCH('Summary of unit costs'!A30,LiteratureCost!$A$2:$A$10,0)),INDEX(InterventionCosts!$L$1:$L$2363,MATCH(A30,IF(InterventionCosts!$F$1:$F$2363="Cost per intervention",InterventionCosts!$A$1:$A$2363),0)))} -> 1481.154 | H30: =G30/exrate -> 79.373085 | I30: {=IF(E30="Literature",INDEX(LiteratureCost!$G$2:$G$22,MATCH('Summary of unit costs'!A30,LiteratureCost!$A$2:$A$22,0)),INDEX(InterventionCosts!$L$1:$L$3432,MATCH(A30,IF(InterventionCosts!$F$1:$F$3432="Unit",InterventionCosts!$A$1:$A$3432),0)))} -> per circumcision | K30: Full service cost- do not have this breakdown
A31: Early infant male circumcision | C31: Number of early infant male circumcisions | E31: Ingredients | F31: MMC | G31: {=IF(E31="Literature",INDEX(LiteratureCost!$I$2:$I$10,MATCH('Summary of unit costs'!A31,LiteratureCost!$A$2:$A$10,0)),INDEX(InterventionCosts!$L$1:$L$2363,MATCH(A31,IF(InterventionCosts!$F$1:$F$2363="Cost per intervention",InterventionCosts!$A$1:$A$2363),0)))} -> 740.577 | H31: =G31/exrate -> 39.686543 | I31: {=IF(E31="Literature",INDEX(LiteratureCost!$G$2:$G$22,MATCH('Summary of unit costs'!A31,LiteratureCost!$A$2:$A$22,0)),INDEX(InterventionCosts!$L$1:$L$3432,MATCH(A31,IF(InterventionCosts!$F$1:$F$3432="Unit",InterventionCosts!$A$1:$A$3432),0)))} -> per circumcision | K31: Assumed half of adult cost
A32: Condom distribution in clinics | C32: Total condoms distributed * 80% | E32: Ingredients | F32: PREV | G32: {=IF(E32="Literature",INDEX(LiteratureCost!$I$2:$I$10,MATCH('Summary of unit costs'!A32,LiteratureCost!$A$2:$A$10,0)),INDEX(InterventionCosts!$L$1:$L$2363,MATCH(A32,IF(InterventionCosts!$F$1:$F$2363="Cost per intervention",InterventionCosts!$A$1:$A$2363),0)))} -> 0.94920714 | H32: =G32/exrate -> 0.050866756 | I32: {=IF(E32="Literature",INDEX(LiteratureCost!$G$2:$G$22,MATCH('Summary of unit costs'!A32,LiteratureCost!$A$2:$A$22,0)),INDEX(InterventionCosts!$L$1:$L$3432,MATCH(A32,IF(InterventionCosts!$F$1:$F$3432="Unit",InterventionCosts!$A$1:$A$3432),0)))} -> per condom distributed | J32: =G32/SUM(Q32:V32) -> 1 | K32: =Q32/$G32 -> 0.82385896 | L32: =R32/$G32 -> 0 | M32: =S32/$G32 -> 0 | N32: =T32/$G32 -> 0 | O32: =U32/$G32 -> 0.17614104 | P32: =V32/$G32 -> 0 | Q32: =SUMIFS(InterventionCosts!$K$2:$K$3432,InterventionCosts!$D$2:$D$3432,'Summary of unit costs'!Q$1,InterventionCosts!$A$2:$A$3432,'Summary of unit costs'!$A32) -> 0.7820128 | R32: =SUMIFS(InterventionCosts!$K$2:$K$3432,InterventionCosts!$D$2:$D$3432,'Summary of unit costs'!R$1,InterventionCosts!$A$2:$A$3432,'Summary of unit costs'!$A32) -> 0 | S32: =SUMIFS(InterventionCosts!$K$2:$K$3432,InterventionCosts!$D$2:$D$3432,'Summary of unit costs'!S$1,InterventionCosts!$A$2:$A$3432,'Summary of unit costs'!$A32) -> 0 | T32: =SUMIFS(InterventionCosts!$K$2:$K$3432,InterventionCosts!$D$2:$D$3432,'Summary of unit costs'!T$1,InterventionCosts!$A$2:$A$3432,'Summary of unit costs'!$A32) -> 0 | U32: =SUMIFS(InterventionCosts!$K$2:$K$3432,InterventionCosts!$D$2:$D$3432,'Summary of unit costs'!U$1,InterventionCosts!$A$2:$A$3432,'Summary of unit costs'!$A32) -> 0.16719434 | V32: =SUMIFS(InterventionCosts!$K$2:$K$3432,InterventionCosts!$D$2:$D$3432,'Summary of unit costs'!V$1,InterventionCosts!$A$2:$A$3432,'Summary of unit costs'!$A32) -> 0
A33: Condom distribution in non-traditional outlets (hotels; shops; malls) | C33: Total condoms distributed * 20% | E33: Ingredients | F33: PREV | G33: {=IF(E33="Literature",INDEX(LiteratureCost!$I$2:$I$10,MATCH('Summary of unit costs'!A33,LiteratureCost!$A$2:$A$10,0)),INDEX(InterventionCosts!$L$1:$L$2363,MATCH(A33,IF(InterventionCosts!$F$1:$F$2363="Cost per intervention",InterventionCosts!$A$1:$A$2363),0)))} -> 1.1164015 | H33: =G33/exrate -> 0.05982648 | I33: {=IF(E33="Literature",INDEX(LiteratureCost!$G$2:$G$22,MATCH('Summary of unit costs'!A33,LiteratureCost!$A$2:$A$22,0)),INDEX(InterventionCosts!$L$1:$L$3432,MATCH(A33,IF(InterventionCosts!$F$1:$F$3432="Unit",InterventionCosts!$A$1:$A$3432),0)))} -> per condom distributed | J33: =G33/SUM(Q33:V33) -> 1 | K33: =Q33/$G33 -> 0.70047632 | L33: =R33/$G33 -> 0 | M33: =S33/$G33 -> 0 | N33: =T33/$G33 -> 0 | O33: =U33/$G33 -> 0.29952368 | P33: =V33/$G33 -> 0 | Q33: =SUMIFS(InterventionCosts!$K$2:$K$3432,InterventionCosts!$D$2:$D$3432,'Summary of unit costs'!Q$1,InterventionCosts!$A$2:$A$3432,'Summary of unit costs'!$A33) -> 0.7820128 | R33: =SUMIFS(InterventionCosts!$K$2:$K$3432,InterventionCosts!$D$2:$D$3432,'Summary of unit costs'!R$1,InterventionCosts!$A$2:$A$3432,'Summary of unit costs'!$A33) -> 0 | S33: =SUMIFS(InterventionCosts!$K$2:$K$3432,InterventionCosts!$D$2:$D$3432,'Summary of unit costs'!S$1,InterventionCosts!$A$2:$A$3432,'Summary of unit costs'!$A33) -> 0 | T33: =SUMIFS(InterventionCosts!$K$2:$K$3432,InterventionCosts!$D$2:$D$3432,'Summary of unit costs'!T$1,InterventionCosts!$A$2:$A$3432,'Summary of unit costs'!$A33) -> 0 | U33: =SUMIFS(InterventionCosts!$K$2:$K$3432,InterventionCosts!$D$2:$D$3432,'Summary of unit costs'!U$1,InterventionCosts!$A$2:$A$3432,'Summary of unit costs'!$A33) -> 0.33438867 | V33: =SUMIFS(InterventionCosts!$K$2:$K$3432,InterventionCosts!$D$2:$D$3432,'Summary of unit costs'!V$1,InterventionCosts!$A$2:$A$3432,'Summary of unit costs'!$A33) -> 0
